Workbook

Sheet Nov-2024-Roster
B1: Type of req: Reason: | C1: =IFERROR(CONCATENATE(" Enter ",'Setting key Duty'!$B$7," for ",'Setting key Duty'!$C$7,", ",'Setting key Duty'!$B$8," for ",'Setting key Duty'!$C$8,", ",'Setting key Duty'!$B$9," for ",'Setting key Duty'!$C$9,", and ",'Setting key Duty'!$B$11," for ",'Setting key Duty'!$C$11,". Use the 'Setting key' tab to customise. Change Date on highlighted cell "),"") -> Enter DM for DM, CS1 for CS1, CS2 for CS2, and SB1 for SB1. Use the 'Setting key' tab to customise. Change Date on highlighted cell
B2: Event Log | I2: C VACC 2 | M2: F VACC 2 | N2: E VACC 1 | O2: T VACC 1 | P2: B VACC 1 | Q2: U VACC 2 | T2: A VACC 1 | U2: V VACC 2 | V2: W VACC 2 | W2: O VACC 2 | X2: N VACC 1 | AA2: R VACC 2 | AB2: P VACC 1 | AE2: S VACC 1 | AZ2: 0.3125+0.0625+0.5 long+stay+pass12 | BB2: 0.3125+0.125 Long hr+aft 1730 | BD2: 0.125+0.125+0.0625 Bef 0730+Aft1730+stay | BG2: 0.125 after 1730 | BI2: stay in+ bef 0730
B3: Rostering | C3: 45597 | D3: =C3+1 -> 45598 | E3: =D3+1 -> 45599 | F3: =E3+1 -> 45600 | G3: =F3+1 -> 45601 | H3: =G3+1 -> 45602 | I3: =H3+1 -> 45603 | J3: =I3+1 -> 45604 | K3: =J3+1 -> 45605 | ... AG3: =AF3+1 -> 45627 | AH3: ='Setting key Duty'!$C7 -> DM | AI3: ='Setting key Duty'!$C8 -> CS1 | AJ3: ='Setting key Duty'!$C9 -> CS2 | AK3: ='Setting key Duty'!$C11 -> SB1 | AL3: ='Setting key Duty'!$C12 -> SB2 | AM3: ='Setting key Duty'!$C13 -> AE | AN3: ='Setting key Duty'!C14 -> EM | AP3: Weekday Duty | AQ3: Weekday Extra | AR3: Weekend Duty | AS3: Weekend Extra | AT3: Duty Point | AU3: Total Duty | AV3: Total Cover | AW3: Total Point | AX3: Total Cover Point | AY3: Bedok RT | AZ3: BTP | BA3: $BTP Point | BB3: Long Cover | BC3: $L Point | BD3: Mid Cover | BE3: $M Point | BF3: Cover Normal Hour | BG3: Cover After Hour | BH3: $PM Point | BI3: Cover Early | BJ3: $AM Point | BK3: ='Setting key Duty'!C52 -> Field Camp | BL3: $FC Point | BM3: ='Setting key Duty'!$C15 -> Block | BN3: ='Setting key Duty'!C17 -> Reserve | BO3: ='Setting key Duty'!$C22 -> AL
B4: Updated on: 26/10/1018 | C4: =TEXT(C3,"ddd") -> Fri | D4: =TEXT(D3,"ddd") -> Sat | E4: =TEXT(E3,"ddd") -> Sun | F4: =TEXT(F3,"ddd") -> Mon | G4: =TEXT(G3,"ddd") -> Tue | H4: =TEXT(H3,"ddd") -> Wed | I4: =TEXT(I3,"ddd") -> Thu | J4: =TEXT(J3,"ddd") -> Fri | ... AG4: =TEXT(AG3,"ddd") -> Sun | AH4: ='Setting key Duty'!$B7 -> DM | AI4: ='Setting key Duty'!$B8 -> CS1 | AJ4: ='Setting key Duty'!$B9 -> CS2 | AK4: ='Setting key Duty'!$B11 -> SB1 | AL4: ='Setting key Duty'!$B12 -> SB2 | AM4: ='Setting key Duty'!$B13 -> AE | AN4: ='Setting key Duty'!B14 -> EM | AY4: BRT | AZ4: $BTP | BB4: $L | BD4: $M | BF4: $N | BG4: $PM | BI4: $AM | BK4: ='Setting key Duty'!B52 -> $FC | BM4: ='Setting key Duty'!$B15 -> 0 | BN4: ='Setting key Duty'!B17 -> RESERVE | BO4: ='Setting key Duty'!$B22 -> AL
A5: X | B5: CFC MUHAMAD HAZMI BIN MOHD ZULKIFLI | C5: OL | D5: AL | E5: AL | H5: CS1 | K5: DM | M5: CS1 | O5: SB1 | Q5: AL | T5: CS2 | U5: AL | V5: CS2 | X5: CS1 | AD5: DM | AF5: DM | AH5: =COUNTIF($C5:$AE5,AH$4) -> 2 | AI5: =COUNTIF($C5:$AE5,AI$4) -> 3 | AJ5: =COUNTIF($C5:$AE5,AJ$4) -> 2 | AK5: =COUNTIF($C5:$AE5,AK$4) -> 1 | AL5: =COUNTIF($C5:$AE5,AL$4) -> 0 | AM5: =COUNTIF($C5:$AE5,AM$4) -> 0 | AN5: =COUNTIF($C5:$AE5,AN$4) -> 0 | AP5: =SUMPRODUCT(--WEEKDAY(C$3:AG$3,2)<6,--((C5:AG5="DM"))+(C5:AG5="CS1")+((C5:AG5="CS2"))+(C5:AG5="SB1")+(C5:AG5="AE")+(C5:AG5="EM")) -> 0 | AR5: =SUMPRODUCT(--WEEKDAY(C$3:AG$3,2)>5,--((C5:AG5="DM"))+(C5:AG5="CS1")+((C5:AG5="CS2"))+(C5:AG5="SB1")+(C5:AG5="AE")+(C5:AG5="EM")) -> 0 | AT5: =(AP5-AQ5)/2+(AR5-AS5) -> 0 | AU5: =AH5+AI5+AJ5+AK5+AM5+AN5 -> 8 | AV5: =BF5+BG5+BI5+BD5+BB5+AZ5+BK5 -> 0 | AW5: =AT5+AX5 -> #VALUE! | AX5: =(BI5*('Setting key Duty'!$I$8+'Setting key Duty'!$I$12))+(BG5*'Setting key Duty'!$I$9)+(BB5*('Setting key Duty'!$I$13+'Setting key Duty'!$I$9))+(AZ5*('Setting key Duty'!$I$13+'Setting key Duty'!$I$12+'Setting key Duty'!$I$11))+(BD5*('Setting key Duty'!$I$8+'Setting key Duty'!$I$9+'Setting key Duty'!$I$12)) -> #VALUE! | AY5: =COUNTIF(C5:AE5,"*BRT*") -> 0 | AZ5: =COUNTIF(A5:AH5,"*$BTP*") -> 0 | BA5: =AZ5*('Setting key Duty'!$I$13+'Setting key Duty'!$I$12+'Setting key Duty'!$I$11) -> #VALUE! | BB5: =COUNTIF(A5:AH5,"*$L*") -> 0 | BC5: =BB5*('Setting key Duty'!$I$13+'Setting key Duty'!$I$9) -> #VALUE! | BD5: =COUNTIF(A5:AH5,"*$M*") -> 0 | BE5: =BD5*('Setting key Duty'!$I$8+'Setting key Duty'!$I$9+'Setting key Duty'!$I$12) -> 0 | BF5: =COUNTIF(AF5:AH5,"*$N*") -> 0 | BG5: =COUNTIF(AF5:AH5,"*$PM*") -> 0 | BH5: =BG5*('Setting key Duty'!$I$9) -> 0 | BI5: =COUNTIF(A5:AH5,"*$AM*") -> 0 | BJ5: =BI5*('Setting key Duty'!$I$12+'Setting key Duty'!$I$8) -> 0 | BK5: =COUNTIF(C5:AH5,"*$FC*") -> 0 | BL5: =BK5*('Setting key Duty'!$J$11+'Setting key Duty'!$I$8) -> 0 | BM5: =COUNTIF($C5:$AE5,BM$4) -> 0 | BN5: =COUNTIF($C5:$AE5,BN$4) -> 0 | BO5: =COUNTIF($C5:$AE5,BO$4) -> 4
B6: CPL MUHAMMAD IZZAN RIZAL | E6: SB1 | H6: SB1 | J6: CS1 | O6: AMPT | S6: CS2 | U6: CS2 | W6: CS1 | AA6: CS2 | AD6: AL | AE6: AL | AF6: AL | AG6: AL | AH6: =COUNTIF($C6:$AE6,AH$4) -> 0 | AI6: =COUNTIF($C6:$AE6,AI$4) -> 2 | AJ6: =COUNTIF($C6:$AE6,AJ$4) -> 3 | AK6: =COUNTIF($C6:$AE6,AK$4) -> 2 | AL6: =COUNTIF($C6:$AE6,AL$4) -> 0 | AM6: =COUNTIF($C6:$AE6,AM$4) -> 0 | AN6: =COUNTIF($C6:$AE6,AN$4) -> 0 | AP6: =SUMPRODUCT(--WEEKDAY(C$3:AG$3,2)<6,--((C6:AG6="DM"))+(C6:AG6="CS1")+((C6:AG6="CS2"))+(C6:AG6="SB1")+(C6:AG6="AE")+(C6:AG6="EM")) -> 0 | AR6: =SUMPRODUCT(--WEEKDAY(C$3:AG$3,2)>5,--((C6:AG6="DM"))+(C6:AG6="CS1")+((C6:AG6="CS2"))+(C6:AG6="SB1")+(C6:AG6="AE")+(C6:AG6="EM")) -> 0 | AT6: =(AP6-AQ6)/2+(AR6-AS6) -> 0 | AU6: =AH6+AI6+AJ6+AK6+AM6+AN6 -> 7 | AV6: =AT6+AX6 -> #VALUE! | AW6: =AT6+AX6 -> #VALUE! | AX6: =(BI6*('Setting key Duty'!$I$8+'Setting key Duty'!$I$12))+(BG6*'Setting key Duty'!$I$9)+(BB6*('Setting key Duty'!$I$13+'Setting key Duty'!$I$9))+(AZ6*('Setting key Duty'!$I$13+'Setting key Duty'!$I$12+'Setting key Duty'!$I$11))+(BD6*('Setting key Duty'!$I$8+'Setting key Duty'!$I$9+'Setting key Duty'!$I$12)) -> #VALUE! | AY6: =COUNTIF(C6:AE6,"*BRT*") -> 0 | AZ6: =COUNTIF(A6:AH6,"*$BTP*") -> 0 | BA6: =AZ6*('Setting key Duty'!$I$13+'Setting key Duty'!$I$12+'Setting key Duty'!$I$11) -> #VALUE! | BB6: =COUNTIF(A6:AH6,"*$L*") -> 0 | BC6: =BB6*('Setting key Duty'!$I$13+'Setting key Duty'!$I$9) -> #VALUE! | BD6: =COUNTIF(A6:AH6,"*$M*") -> 0 | BE6: =BD6*('Setting key Duty'!$I$8+'Setting key Duty'!$I$9+'Setting key Duty'!$I$12) -> 0 | BF6: =COUNTIF(AF6:AH6,"*$N*") -> 0 | BG6: =COUNTIF(AF6:AH6,"*$PM*") -> 0 | BH6: =BG6*('Setting key Duty'!$I$9) -> 0 | BI6: =COUNTIF(A6:AH6,"*$AM*") -> 0 | BJ6: =BI6*('Setting key Duty'!$I$12+'Setting key Duty'!$I$8) -> 0 | BK6: =COUNTIF(C6:AH6,"*$FC*") -> 0 | BL6: =BK6*('Setting key Duty'!$J$11+'Setting key Duty'!$I$8) -> 0 | BM6: =COUNTIF($C6:$AE6,BM$4) -> 0 | BN6: =COUNTIF($C6:$AE6,BN$4) -> 0 | BO6: =COUNTIF($C6:$AE6,BO$4) -> 2
B7: LCP KARTHIKRAM KRISHNAN | C7: SB1 | G7: CS2 | I7: CS1 | L7: DM | O7: AMPT | P7: CS2 | V7: CS1 | Z7: DM | AG7: DM | AH7: =COUNTIF($C7:$D7,AH$4) -> 0 | AI7: =COUNTIF($C7:$D7,AI$4) -> 0 | AJ7: =COUNTIF($C7:$D7,AJ$4) -> 0 | AK7: =COUNTIF($C7:$D7,AK$4) -> 1 | AL7: =COUNTIF($C7:$D7,AL$4) -> 0 | AM7: =COUNTIF($C7:$D7,AM$4) -> 0 | AN7: =COUNTIF($C7:$D7,AN$4) -> 0 | AP7: =SUMPRODUCT(--WEEKDAY(C$3:AG$3,2)<6,--((C7:AG7="DM"))+(C7:AG7="CS1")+((C7:AG7="CS2"))+(C7:AG7="SB1")+(C7:AG7="AE")+(C7:AG7="EM")) -> 0 | AR7: =SUMPRODUCT(--WEEKDAY(C$3:AG$3,2)>5,--((C7:AG7="DM"))+(C7:AG7="CS1")+((C7:AG7="CS2"))+(C7:AG7="SB1")+(C7:AG7="AE")+(C7:AG7="EM")) -> 0 | AT7: =(AP7-AQ7)/2+(AR7-AS7) -> 0 | AU7: =AH7+AI7+AJ7+AK7+AM7+AN7 -> 1 | AV7: =BF7+BG7+BI7+BD7+BB7+AZ7+BK7 -> 0 | AW7: =AT7+AX7 -> #VALUE! | AX7: =(BI7*('Setting key Duty'!$I$8+'Setting key Duty'!$I$12))+(BG7*'Setting key Duty'!$I$9)+(BB7*('Setting key Duty'!$I$13+'Setting key Duty'!$I$9))+(AZ7*('Setting key Duty'!$I$13+'Setting key Duty'!$I$12+'Setting key Duty'!$I$11))+(BD7*('Setting key Duty'!$I$8+'Setting key Duty'!$I$9+'Setting key Duty'!$I$12)) -> #VALUE! | AY7: =COUNTIF(C7:D7,"*BRT*") -> 0 | AZ7: =COUNTIF(A7:AH7,"*$BTP*") -> 0 | BA7: =AZ7*('Setting key Duty'!$I$13+'Setting key Duty'!$I$12+'Setting key Duty'!$I$11) -> #VALUE! | BB7: =COUNTIF(A7:AH7,"*$L*") -> 0 | BC7: =BB7*('Setting key Duty'!$I$13+'Setting key Duty'!$I$9) -> #VALUE! | BD7: =COUNTIF(A7:AH7,"*$M*") -> 0 | BE7: =BD7*('Setting key Duty'!$I$8+'Setting key Duty'!$I$9+'Setting key Duty'!$I$12) -> 0 | BF7: =COUNTIF(A7:AH7,"*$N*") -> 0 | BG7: =COUNTIF(AG7:AH7,"*$PM*") -> 0 | BH7: =BG7*('Setting key Duty'!$I$9) -> 0 | BI7: =COUNTIF(A7:AH7,"*$AM*") -> 0 | BJ7: =BI7*('Setting key Duty'!$I$12+'Setting key Duty'!$I$8) -> 0 | BK7: =COUNTIF(C7:AH7,"*$FC*") -> 0 | BL7: =BK7*('Setting key Duty'!$J$11+'Setting key Duty'!$I$8) -> 0 | BM7: =COUNTIF($C7:$D7,BM$4) -> 0 | BN7: =COUNTIF($C7:$D7,BN$4) -> 0 | BO7: =COUNTIF($C7:$D7,BO$4) -> 0
B8: CPL MUHAMMAD AQIL BIN ABDULLAH | V8: SB1 | AA8: DM | AC8: SB1 | AG8: CS1 | AP8: =SUMPRODUCT(--WEEKDAY(C$3:AG$3,2)<6,--((C8:AG8="DM"))+(C8:AG8="CS1")+((C8:AG8="CS2"))+(C8:AG8="SB1")+(C8:AG8="AE")+(C8:AG8="EM")) -> 0 | AR8: =SUMPRODUCT(--WEEKDAY(C$3:AG$3,2)>5,--((C8:AG8="DM"))+(C8:AG8="CS1")+((C8:AG8="CS2"))+(C8:AG8="SB1")+(C8:AG8="AE")+(C8:AG8="EM")) -> 0
B9: LCP FARABI BIN ZULKIFLI | C9: AE | I9: SB1 | K9: CS2 | N9: SB1 | Q9: CS1 | V9: AE | X9: AL | AA9: AL | AB9: SB1 | AE9: AL | AG9: CS2 | AP9: =SUMPRODUCT(--WEEKDAY(C$3:AG$3,2)<6,--((C9:AG9="DM"))+(C9:AG9="CS1")+((C9:AG9="CS2"))+(C9:AG9="SB1")+(C9:AG9="AE")+(C9:AG9="EM")) -> 0 | AR9: =SUMPRODUCT(--WEEKDAY(C$3:AG$3,2)>5,--((C9:AG9="DM"))+(C9:AG9="CS1")+((C9:AG9="CS2"))+(C9:AG9="SB1")+(C9:AG9="AE")+(C9:AG9="EM")) -> 0 | AT9: =(AP9-AQ9)/2+(AR9-AS9) -> 0 | AU9: =AH9+AI9+AJ9+AK9+AM9+AN9 -> 0 | AV9: =BF9+BG9+BI9+BD9+BB9+AZ9+BK9 -> 0 | AW9: =AT9+AX9 -> #VALUE! | AX9: =(BI9*('Setting key Duty'!$I$8+'Setting key Duty'!$I$12))+(BG9*'Setting key Duty'!$I$9)+(BB9*('Setting key Duty'!$I$13+'Setting key Duty'!$I$9))+(AZ9*('Setting key Duty'!$I$13+'Setting key Duty'!$I$12+'Setting key Duty'!$I$11))+(BD9*('Setting key Duty'!$I$8+'Setting key Duty'!$I$9+'Setting key Duty'!$I$12)) -> #VALUE! | AY9: =COUNTIF(D9:Z9,"*BRT*") -> 0 | AZ9: =COUNTIF(A9:AH9,"*$BTP*") -> 0 | BA9: =AZ9*('Setting key Duty'!$I$13+'Setting key Duty'!$I$12+'Setting key Duty'!$I$11) -> #VALUE! | BB9: =COUNTIF(A9:AH9,"*$L*") -> 0 | BC9: =BB9*('Setting key Duty'!$I$13+'Setting key Duty'!$I$9) -> #VALUE! | BD9: =COUNTIF(A9:AH9,"*$M*") -> 0 | BE9: =BD9*('Setting key Duty'!$I$8+'Setting key Duty'!$I$9+'Setting key Duty'!$I$12) -> 0 | BF9: =COUNTIF(AH9,"*$N*") -> 0 | BG9: =COUNTIF(AH9,"*$PM*") -> 0 | BH9: =BG9*('Setting key Duty'!$I$9) -> 0 | BI9: =COUNTIF(A9:AH9,"*$AM*") -> 0 | BJ9: =BI9*('Setting key Duty'!$I$12+'Setting key Duty'!$I$8) -> 0 | BK9: =COUNTIF(D9:AH9,"*$FC*") -> 0 | BL9: =BK9*('Setting key Duty'!$J$11+'Setting key Duty'!$I$8) -> 0 | BM9: =COUNTIF($D9:$Z9,BM$4) -> 0 | BN9: =COUNTIF($D9:$Z9,BN$4) -> 0 | BO9: =COUNTIF($D9:$Z9,BO$4) -> 1
B10: CFC MOHAMAD HIDAYAT BIN MOHAMAD YUSOFF | C10: AL | E10: DM | J10: SB1 | M10: DM | O10: DA | Q10: DM | V10: DM | X10: AL | AA10: CS1 | AD10: CS1 | AH10: =COUNTIF($C10:$AE10,AH$4) -> 4 | AI10: =COUNTIF($C10:$AE10,AI$4) -> 2 | AJ10: =COUNTIF($C10:$AE10,AJ$4) -> 0 | AK10: =COUNTIF($C10:$AE10,AK$4) -> 1 | AL10: =COUNTIF($C10:$AE10,AL$4) -> 0 | AM10: =COUNTIF($C10:$AE10,AM$4) -> 0 | AN10: =COUNTIF($C10:$AE10,AN$4) -> 0 | AP10: =SUMPRODUCT(--WEEKDAY(C$3:AG$3,2)<6,--((C10:AG10="DM"))+(C10:AG10="CS1")+((C10:AG10="CS2"))+(C10:AG10="SB1")+(C10:AG10="AE")+(C10:AG10="EM")) -> 0 | AR10: =SUMPRODUCT(--WEEKDAY(C$3:AG$3,2)>5,--((C10:AG10="DM"))+(C10:AG10="CS1")+((C10:AG10="CS2"))+(C10:AG10="SB1")+(C10:AG10="AE")+(C10:AG10="EM")) -> 0 | AT10: =(AP10-AQ10)/2+(AR10-AS10) -> 0 | AU10: =AH10+AI10+AJ10+AK10+AM10+AN10 -> 7 | AV10: =BF10+BG10+BI10+BD10+BB10+AZ10+BK10 -> 0 | AW10: =AT10+AX10 -> #VALUE! | AX10: =(BI10*('Setting key Duty'!$I$8+'Setting key Duty'!$I$12))+(BG10*'Setting key Duty'!$I$9)+(BB10*('Setting key Duty'!$I$13+'Setting key Duty'!$I$9))+(AZ10*('Setting key Duty'!$I$13+'Setting key Duty'!$I$12+'Setting key Duty'!$I$11))+(BD10*('Setting key Duty'!$I$8+'Setting key Duty'!$I$9+'Setting key Duty'!$I$12)) -> #VALUE! | AY10: =COUNTIF(C10:AE10,"*BRT*") -> 0 | AZ10: =COUNTIF(A10:AH10,"*$BTP*") -> 0 | BA10: =AZ10*('Setting key Duty'!$I$13+'Setting key Duty'!$I$12+'Setting key Duty'!$I$11) -> #VALUE! | BB10: =COUNTIF(A10:AH10,"*$L*") -> 0 | BC10: =BB10*('Setting key Duty'!$I$13+'Setting key Duty'!$I$9) -> #VALUE! | BD10: =COUNTIF(A10:AH10,"*$M*") -> 0 | BE10: =BD10*('Setting key Duty'!$I$8+'Setting key Duty'!$I$9+'Setting key Duty'!$I$12) -> 0 | BF10: =COUNTIF(A10:AH10,"*$N*") -> 0 | BG10: =COUNTIF(AF10:AH10,"*$PM*") -> 0 | BH10: =BG10*('Setting key Duty'!$I$9) -> 0 | BI10: =COUNTIF(A10:AH10,"*$AM*") -> 0 | BJ10: =BI10*('Setting key Duty'!$I$12+'Setting key Duty'!$I$8) -> 0 | BK10: =COUNTIF(C10:AH10,"*$FC*") -> 0 | BL10: =BK10*('Setting key Duty'!$J$11+'Setting key Duty'!$I$8) -> 0 | BM10: =COUNTIF($C10:$AE10,BM$4) -> 0 | BN10: =COUNTIF($C10:$AE10,BN$4) -> 0 | BO10: =COUNTIF($C10:$AE10,BO$4) -> 2
B11: LCP MUHAMMAD KHIDIR BIN ZAKARIA | E11: CS2 | G11: SB1 | L11: CS1 | N11: CS1 | Q11: CS2 | U11: CS1 | W11: MA | X11: AL | Y11: OL | Z11: OL | AA11: AL | AC11: CS2 | AE11: CS1 | AP11: =SUMPRODUCT(--WEEKDAY(C$3:AG$3,2)<6,--((C11:AG11="DM"))+(C11:AG11="CS1")+((C11:AG11="CS2"))+(C11:AG11="SB1")+(C11:AG11="AE")+(C11:AG11="EM")) -> 0 | AR11: =SUMPRODUCT(--WEEKDAY(C$3:AG$3,2)>5,--((C11:AG11="DM"))+(C11:AG11="CS1")+((C11:AG11="CS2"))+(C11:AG11="SB1")+(C11:AG11="AE")+(C11:AG11="EM")) -> 0 | AT11: =(AP11-AQ11)/2+(AR11-AS11) -> 0 | AU11: =AH11+AI11+AJ11+AK11+AM11+AN11 -> 0 | AV11: =BF11+BG11+BI11+BD11+BB11+AZ11+BK11 -> 0 | AW11: =AT11+AX11 -> #VALUE! | AX11: =(BI11*('Setting key Duty'!$I$8+'Setting key Duty'!$I$12))+(BG11*'Setting key Duty'!$I$9)+(BB11*('Setting key Duty'!$I$13+'Setting key Duty'!$I$9))+(AZ11*('Setting key Duty'!$I$13+'Setting key Duty'!$I$12+'Setting key Duty'!$I$11))+(BD11*('Setting key Duty'!$I$8+'Setting key Duty'!$I$9+'Setting key Duty'!$I$12)) -> #VALUE! | AY11: =COUNTIF(#REF!,"*BRT*") -> #REF! | AZ11: =COUNTIF(A11:AH11,"*$BTP*") -> 0 | BA11: =AZ11*('Setting key Duty'!$I$13+'Setting key Duty'!$I$12+'Setting key Duty'!$I$11) -> #VALUE! | BB11: =COUNTIF(A11:AH11,"*$L*") -> 0 | BC11: =BB11*('Setting key Duty'!$I$13+'Setting key Duty'!$I$9) -> #VALUE! | BD11: =COUNTIF(A11:AH11,"*$M*") -> 0 | BE11: =BD11*('Setting key Duty'!$I$8+'Setting key Duty'!$I$9+'Setting key Duty'!$I$12) -> 0 | BF11: =COUNTIF(AH11,"*$N*") -> 0 | BG11: =COUNTIF(AH11,"*$PM*") -> 0 | BH11: =BG11*('Setting key Duty'!$I$9) -> 0 | BI11: =COUNTIF(A11:AH11,"*$AM*") -> 0 | BJ11: =BI11*('Setting key Duty'!$I$12+'Setting key Duty'!$I$8) -> 0 | BK11: =COUNTIF(E11:AH11,"*$FC*") -> 0 | BL11: =BK11*('Setting key Duty'!$J$11+'Setting key Duty'!$I$8) -> 0 | BM11: =COUNTIF(#REF!,BM$4) -> #REF! | BN11: =COUNTIF(#REF!,BN$4) -> #REF! | BO11: =COUNTIF(#REF!,BO$4) -> #REF!
B12: CPL MOHD AMEER KHAN S/O BASHIR ISMAIL | D12: CS2 | H12: AE | J12: AL | L12: CS2 | Q12: SB1 | T12: SB1 | V12: MC | W12: MC | X12: AL | Y12: AL | Z12: AL | AB12: AE | AE12: CS2 | AP12: =SUMPRODUCT(--WEEKDAY(C$3:AG$3,2)<6,--((C12:AG12="DM"))+(C12:AG12="CS1")+((C12:AG12="CS2"))+(C12:AG12="SB1")+(C12:AG12="AE")+(C12:AG12="EM")) -> 0 | AR12: =SUMPRODUCT(--WEEKDAY(C$3:AG$3,2)>5,--((C12:AG12="DM"))+(C12:AG12="CS1")+((C12:AG12="CS2"))+(C12:AG12="SB1")+(C12:AG12="AE")+(C12:AG12="EM")) -> 0 | AT12: =(AP12-AQ12)/2+(AR12-AS12) -> 0 | AU12: =AH12+AI12+AJ12+AK12+AM12+AN12 -> 0 | AV12: =BF12+BG12+BI12+BD12+BB12+AZ12+BK12 -> 0 | AW12: =AT12+AX12 -> #VALUE! | AX12: =(BI12*('Setting key Duty'!$I$8+'Setting key Duty'!$I$12))+(BG12*'Setting key Duty'!$I$9)+(BB12*('Setting key Duty'!$I$13+'Setting key Duty'!$I$9))+(AZ12*('Setting key Duty'!$I$13+'Setting key Duty'!$I$12+'Setting key Duty'!$I$11))+(BD12*('Setting key Duty'!$I$8+'Setting key Duty'!$I$9+'Setting key Duty'!$I$12)) -> #VALUE! | AY12: =COUNTIF(D12:AC12,"*BRT*") -> 0 | AZ12: =COUNTIF(A12:AH12,"*$BTP*") -> 0 | BA12: =AZ12*('Setting key Duty'!$I$13+'Setting key Duty'!$I$12+'Setting key Duty'!$I$11) -> #VALUE! | BB12: =COUNTIF(A12:AH12,"*$L*") -> 0 | BC12: =BB12*('Setting key Duty'!$I$13+'Setting key Duty'!$I$9) -> #VALUE! | BD12: =COUNTIF(A12:AH12,"*$M*") -> 0 | BE12: =BD12*('Setting key Duty'!$I$8+'Setting key Duty'!$I$9+'Setting key Duty'!$I$12) -> 0 | BF12: =COUNTIF(AF12:AH12,"*$N*") -> 0 | BG12: =COUNTIF(AF12:AH12,"*$PM*") -> 0 | BH12: =BG12*('Setting key Duty'!$I$9) -> 0 | BI12: =COUNTIF(A12:AH12,"*$AM*") -> 0 | BJ12: =BI12*('Setting key Duty'!$I$12+'Setting key Duty'!$I$8) -> 0 | BK12: =COUNTIF(D12:AH12,"*$FC*") -> 0 | BL12: =BK12*('Setting key Duty'!$J$11+'Setting key Duty'!$I$8) -> 0 | BM12: =COUNTIF($D12:$AE12,BM$4) -> 0 | BN12: =COUNTIF($D12:$AE12,BN$4) -> 0 | BO12: =COUNTIF($D12:$AE12,BO$4) -> 4
B13: LCP ALPHA KELVIN ISAAC BIN MUHAMMAD MCKEVIN LAWRENCE | E13: R $FC | F13: R $FC | G13: R $FC | H13: R $FC | I13: R $FC | N13: CS2 | P13: SB1 | R13: CS2 | U13: SB1 | V13: C $M 12 KM RM (1400-2359) | X13: CS2 | AB13: E $M ISAD (0530-2000) | AC13: AE | AP13: =SUMPRODUCT(--WEEKDAY(C$3:AG$3,2)<6,--((C13:AG13="DM"))+(C13:AG13="CS1")+((C13:AG13="CS2"))+(C13:AG13="SB1")+(C13:AG13="AE")+(C13:AG13="EM")) -> 0 | AR13: =SUMPRODUCT(--WEEKDAY(C$3:AG$3,2)>5,--((C13:AG13="DM"))+(C13:AG13="CS1")+((C13:AG13="CS2"))+(C13:AG13="SB1")+(C13:AG13="AE")+(C13:AG13="EM")) -> 0 | AT13: =(AP13-AQ13)/2+(AR13-AS13) -> 0 | AU13: =AH13+AI13+AJ13+AK13+AM13+AN13 -> 0 | AV13: =BF13+BG13+BI13+BD13+BB13+AZ13+BK13 -> 7 | AW13: =AT13+AX13 -> #VALUE! | AX13: =(BI13*('Setting key Duty'!$I$8+'Setting key Duty'!$I$12))+(BG13*'Setting key Duty'!$I$9)+(BB13*('Setting key Duty'!$I$13+'Setting key Duty'!$I$9))+(AZ13*('Setting key Duty'!$I$13+'Setting key Duty'!$I$12+'Setting key Duty'!$I$11))+(BD13*('Setting key Duty'!$I$8+'Setting key Duty'!$I$9+'Setting key Duty'!$I$12)) -> #VALUE! | AY13: =COUNTIF(D13:X13,"*BRT*") -> 0 | AZ13: =COUNTIF(A13:AH13,"*$BTP*") -> 0 | BA13: =AZ13*('Setting key Duty'!$I$13+'Setting key Duty'!$I$12+'Setting key Duty'!$I$11) -> #VALUE! | BB13: =COUNTIF(A13:AH13,"*$L*") -> 0 | BC13: =BB13*('Setting key Duty'!$I$13+'Setting key Duty'!$I$9) -> #VALUE! | BD13: =COUNTIF(A13:AH13,"*$M*") -> 2 | BE13: =BD13*('Setting key Duty'!$I$8+'Setting key Duty'!$I$9+'Setting key Duty'!$I$12) -> 1.125 | BF13: =COUNTIF(AH13,"*$N*") -> 0 | BG13: =COUNTIF(AH13,"*$PM*") -> 0 | BH13: =BG13*('Setting key Duty'!$I$9) -> 0 | BI13: =COUNTIF(A13:AH13,"*$AM*") -> 0 | BJ13: =BI13*('Setting key Duty'!$I$12+'Setting key Duty'!$I$8) -> 0 | BK13: =COUNTIF(D13:AH13,"*$FC*") -> 5 | BL13: =BK13*('Setting key Duty'!$J$11+'Setting key Duty'!$I$8) -> 0.625 | BM13: =COUNTIF($D13:$X13,BM$4) -> 0 | BN13: =COUNTIF($D13:$X13,BN$4) -> 0 | BO13: =COUNTIF($D13:$X13,BO$4) -> 0
B14: LCP RAZIN HILMANSYAH BIN ROSLI | D14: B (MALAYSIA) | E14: CS1 | H14: CS2 | J14: DM | O14: AMPT | P14: DM | R14: SB1 | U14: DM | X14: AL | Y14: OL | Z14: OL | AA14: AL | AB14: AL | AC14: AL | AD14: MA | AE14: DM | AH14: =COUNTIF($C14:$AA14,AH$4) -> 3 | AI14: =COUNTIF($C14:$AA14,AI$4) -> 1 | AJ14: =COUNTIF($C14:$AA14,AJ$4) -> 1 | AK14: =COUNTIF($C14:$AA14,AK$4) -> 1 | AL14: =COUNTIF($C14:$AA14,AL$4) -> 0 | AM14: =COUNTIF($C14:$AA14,AM$4) -> 0 | AN14: =COUNTIF($C14:$AA14,AN$4) -> 0 | AP14: =SUMPRODUCT(--WEEKDAY(C$3:AG$3,2)<6,--((C14:AG14="DM"))+(C14:AG14="CS1")+((C14:AG14="CS2"))+(C14:AG14="SB1")+(C14:AG14="AE")+(C14:AG14="EM")) -> 0 | AR14: =SUMPRODUCT(--WEEKDAY(C$3:AG$3,2)>5,--((C14:AG14="DM"))+(C14:AG14="CS1")+((C14:AG14="CS2"))+(C14:AG14="SB1")+(C14:AG14="AE")+(C14:AG14="EM")) -> 0 | AT14: =(AP14-AQ14)/2+(AR14-AS14) -> 0 | AU14: =AH14+AI14+AJ14+AK14+AM14+AN14 -> 6 | AV14: =BF14+BG14+BI14+BD14+BB14+AZ14+BK14 -> 0 | AW14: =AT14+AX14 -> #VALUE! | AX14: =(BI14*('Setting key Duty'!$I$8+'Setting key Duty'!$I$12))+(BG14*'Setting key Duty'!$I$9)+(BB14*('Setting key Duty'!$I$13+'Setting key Duty'!$I$9))+(AZ14*('Setting key Duty'!$I$13+'Setting key Duty'!$I$12+'Setting key Duty'!$I$11))+(BD14*('Setting key Duty'!$I$8+'Setting key Duty'!$I$9+'Setting key Duty'!$I$12)) -> #VALUE! | AY14: =COUNTIF(C14:AA14,"*BRT*") -> 0 | AZ14: =COUNTIF(A14:AH14,"*$BTP*") -> 0 | BA14: =AZ14*('Setting key Duty'!$I$13+'Setting key Duty'!$I$12+'Setting key Duty'!$I$11) -> #VALUE! | BB14: =COUNTIF(A14:AH14,"*$L*") -> 0 | BC14: =BB14*('Setting key Duty'!$I$13+'Setting key Duty'!$I$9) -> #VALUE! | BD14: =COUNTIF(A14:AH14,"*$M*") -> 0 | BE14: =BD14*('Setting key Duty'!$I$8+'Setting key Duty'!$I$9+'Setting key Duty'!$I$12) -> 0 | BF14: =COUNTIF(A14:AH14,"*$N*") -> 0 | BG14: =COUNTIF(AH14,"*$PM*") -> 0 | BH14: =BG14*('Setting key Duty'!$I$9) -> 0 | BI14: =COUNTIF(A14:AH14,"*$AM*") -> 0 | BJ14: =BI14*('Setting key Duty'!$I$12+'Setting key Duty'!$I$8) -> 0 | BK14: =COUNTIF(C14:AH14,"*$FC*") -> 0 | BL14: =BK14*('Setting key Duty'!$J$11+'Setting key Duty'!$I$8) -> 0 | BM14: =COUNTIF($C14:$AA14,BM$4) -> 0 | BN14: =COUNTIF($C14:$AA14,BN$4) -> 0 | BO14: =COUNTIF($C14:$AA14,BO$4) -> 2
B15: LCP RICKY NG RUIQI | C15: CS1 | H15: AMPT | V15: AMPT | Y15: CS1 | AB15: DM | AG15: SB1 | AH15: =COUNTIF($D15:$AC15,AH$4) -> 1 | AI15: =COUNTIF($D15:$AC15,AI$4) -> 1 | AJ15: =COUNTIF($D15:$AC15,AJ$4) -> 0 | AK15: =COUNTIF($D15:$AC15,AK$4) -> 0 | AL15: =COUNTIF($D15:$AC15,AL$4) -> 0 | AM15: =COUNTIF($D15:$AC15,AM$4) -> 0 | AN15: =COUNTIF($D15:$AC15,AN$4) -> 0 | AP15: =SUMPRODUCT(--WEEKDAY(C$3:AG$3,2)<6,--((C15:AG15="DM"))+(C15:AG15="CS1")+((C15:AG15="CS2"))+(C15:AG15="SB1")+(C15:AG15="AE")+(C15:AG15="EM")) -> 0 | AR15: =SUMPRODUCT(--WEEKDAY(C$3:AG$3,2)>5,--((C15:AG15="DM"))+(C15:AG15="CS1")+((C15:AG15="CS2"))+(C15:AG15="SB1")+(C15:AG15="AE")+(C15:AG15="EM")) -> 0 | AT15: =(AP15-AQ15)/2+(AR15-AS15) -> 0 | AU15: =AH15+AI15+AJ15+AK15+AM15+AN15 -> 2 | AV15: =BF15+BG15+BI15+BD15+BB15+AZ15+BK15 -> 0 | AW15: =AT15+AX15 -> #VALUE! | AX15: =(BI15*('Setting key Duty'!$I$8+'Setting key Duty'!$I$12))+(BG15*'Setting key Duty'!$I$9)+(BB15*('Setting key Duty'!$I$13+'Setting key Duty'!$I$9))+(AZ15*('Setting key Duty'!$I$13+'Setting key Duty'!$I$12+'Setting key Duty'!$I$11))+(BD15*('Setting key Duty'!$I$8+'Setting key Duty'!$I$9+'Setting key Duty'!$I$12)) -> #VALUE! | AY15: =COUNTIF(C15:AC15,"*BRT*") -> 0 | AZ15: =COUNTIF(A15:AH15,"*$BTP*") -> 0 | BA15: =AZ15*('Setting key Duty'!$I$13+'Setting key Duty'!$I$12+'Setting key Duty'!$I$11) -> #VALUE! | BB15: =COUNTIF(A15:AH15,"*$L*") -> 0 | BC15: =BB15*('Setting key Duty'!$I$13+'Setting key Duty'!$I$9) -> #VALUE! | BD15: =COUNTIF(A15:AH15,"*$M*") -> 0 | BE15: =BD15*('Setting key Duty'!$I$8+'Setting key Duty'!$I$9+'Setting key Duty'!$I$12) -> 0 | BF15: =COUNTIF(AH15,"*$N*") -> 0 | BG15: =COUNTIF(AH15,"*$PM*") -> 0 | BH15: =BG15*('Setting key Duty'!$I$9) -> 0 | BI15: =COUNTIF(A15:AH15,"*$AM*") -> 0 | BJ15: =BI15*('Setting key Duty'!$I$12+'Setting key Duty'!$I$8) -> 0 | BK15: =COUNTIF(C15:AH15,"*$FC*") -> 0 | BL15: =BK15*('Setting key Duty'!$J$11+'Setting key Duty'!$I$8) -> 0 | BM15: =COUNTIF($C15:$AC15,BM$4) -> 0 | BN15: =COUNTIF($C15:$AC15,BN$4) -> 0 | BO15: =COUNTIF($C15:$AC15,BO$4) -> 0
B16: LCP MUHAMED AMIR BIN AHMAD FAIZAL | D16: SB1 | F16: BAIL | H16: DM | K16: CS1 | O16: AMPT | V16: AMPT | W16: AL | X16: AL | Y16: AL | Z16: AL | AD16: SB1 | AF16: CS2 | AH16: =COUNTIF($C16:$AA16,AH$4) -> 1 | AI16: =COUNTIF($C16:$AA16,AI$4) -> 1 | AJ16: =COUNTIF($C16:$AA16,AJ$4) -> 0 | AK16: =COUNTIF($C16:$AA16,AK$4) -> 1 | AL16: =COUNTIF($C16:$AA16,AL$4) -> 0 | AM16: =COUNTIF($C16:$AA16,AM$4) -> 0 | AN16: =COUNTIF($C16:$AA16,AN$4) -> 0 | AP16: =SUMPRODUCT(--WEEKDAY(C$3:AG$3,2)<6,--((C16:AG16="DM"))+(C16:AG16="CS1")+((C16:AG16="CS2"))+(C16:AG16="SB1")+(C16:AG16="AE")+(C16:AG16="EM")) -> 0 | AR16: =SUMPRODUCT(--WEEKDAY(C$3:AG$3,2)>5,--((C16:AG16="DM"))+(C16:AG16="CS1")+((C16:AG16="CS2"))+(C16:AG16="SB1")+(C16:AG16="AE")+(C16:AG16="EM")) -> 0 | AT16: =(AP16-AQ16)/2+(AR16-AS16) -> 0 | AU16: =AH16+AI16+AJ16+AK16+AM16+AN16 -> 3 | AV16: =BF16+BG16+BI16+BD16+BB16+AZ16+BK16 -> 0 | AW16: =AT16+AX16 -> #VALUE! | AX16: =(BI16*('Setting key Duty'!$I$8+'Setting key Duty'!$I$12))+(BG16*'Setting key Duty'!$I$9)+(BB16*('Setting key Duty'!$I$13+'Setting key Duty'!$I$9))+(AZ16*('Setting key Duty'!$I$13+'Setting key Duty'!$I$12+'Setting key Duty'!$I$11))+(BD16*('Setting key Duty'!$I$8+'Setting key Duty'!$I$9+'Setting key Duty'!$I$12)) -> #VALUE! | AY16: =COUNTIF(C16:AA16,"*BRT*") -> 0 | AZ16: =COUNTIF(A16:AH16,"*$BTP*") -> 0 | BA16: =AZ16*('Setting key Duty'!$I$13+'Setting key Duty'!$I$12+'Setting key Duty'!$I$11) -> #VALUE! | BB16: =COUNTIF(A16:AH16,"*$L*") -> 0 | BC16: =BB16*('Setting key Duty'!$I$13+'Setting key Duty'!$I$9) -> #VALUE! | BD16: =COUNTIF(A16:AH16,"*$M*") -> 0 | BE16: =BD16*('Setting key Duty'!$I$8+'Setting key Duty'!$I$9+'Setting key Duty'!$I$12) -> 0 | BF16: =COUNTIF(A16:AH16,"*$N*") -> 0 | BG16: =COUNTIF(AH16,"*$PM*") -> 0 | BH16: =BG16*('Setting key Duty'!$I$9) -> 0 | BI16: =COUNTIF(A16:AH16,"*$AM*") -> 0 | BJ16: =BI16*('Setting key Duty'!$I$12+'Setting key Duty'!$I$8) -> 0 | BK16: =COUNTIF(C16:AH16,"*$FC*") -> 0 | BL16: =BK16*('Setting key Duty'!$J$11+'Setting key Duty'!$I$8) -> 0 | BM16: =COUNTIF($C16:$AA16,BM$4) -> 0 | BN16: =COUNTIF($C16:$AA16,BN$4) -> 0 | BO16: =COUNTIF($C16:$AA16,BO$4) -> 4
B17: LCP MARK TAN YIH | C17: CS2 | F17: CS1 | H17: AMPT | J17: OL | K17: OL | L17: OL | M17: SB1 | P17: CS1 | T17: AL | U17: AL | W17: SB1 | Z17: CS1 | AB17: CS1 | AD17: CS2 | AP17: =SUMPRODUCT(--WEEKDAY(C$3:AG$3,2)<6,--((C17:AG17="DM"))+(C17:AG17="CS1")+((C17:AG17="CS2"))+(C17:AG17="SB1")+(C17:AG17="AE")+(C17:AG17="EM")) -> 0 | AR17: =SUMPRODUCT(--WEEKDAY(C$3:AG$3,2)>5,--((C17:AG17="DM"))+(C17:AG17="CS1")+((C17:AG17="CS2"))+(C17:AG17="SB1")+(C17:AG17="AE")+(C17:AG17="EM")) -> 0 | AT17: =(AP17-AQ17)/2+(AR17-AS17) -> 0 | AU17: =AH17+AI17+AJ17+AK17+AM17+AN17 -> 0 | AV17: =BF17+BG17+BI17+BD17+BB17+AZ17+BK17 -> 0 | AW17: =AT17+AX17 -> #VALUE! | AX17: =(BI17*('Setting key Duty'!$I$8+'Setting key Duty'!$I$12))+(BG17*'Setting key Duty'!$I$9)+(BB17*('Setting key Duty'!$I$13+'Setting key Duty'!$I$9))+(AZ17*('Setting key Duty'!$I$13+'Setting key Duty'!$I$12+'Setting key Duty'!$I$11))+(BD17*('Setting key Duty'!$I$8+'Setting key Duty'!$I$9+'Setting key Duty'!$I$12)) -> #VALUE! | AY17: =COUNTIF(E17:AA17,"*BRT*") -> 0 | AZ17: =COUNTIF(A17:AH17,"*$BTP*") -> 0 | BA17: =AZ17*('Setting key Duty'!$I$13+'Setting key Duty'!$I$12+'Setting key Duty'!$I$11) -> #VALUE! | BB17: =COUNTIF(A17:AH17,"*$L*") -> 0 | BC17: =BB17*('Setting key Duty'!$I$13+'Setting key Duty'!$I$9) -> #VALUE! | BD17: =COUNTIF(A17:AH17,"*$M*") -> 0 | BE17: =BD17*('Setting key Duty'!$I$8+'Setting key Duty'!$I$9+'Setting key Duty'!$I$12) -> 0 | BF17: =COUNTIF(AG17:AH17,"*$N*") -> 0 | BG17: =COUNTIF(AG17:AH17,"*$PM*") -> 0 | BH17: =BG17*('Setting key Duty'!$I$9) -> 0 | BI17: =COUNTIF(A17:AH17,"*$AM*") -> 0 | BJ17: =BI17*('Setting key Duty'!$I$12+'Setting key Duty'!$I$8) -> 0 | BK17: =COUNTIF(E17:AH17,"*$FC*") -> 0 | BL17: =BK17*('Setting key Duty'!$J$11+'Setting key Duty'!$I$8) -> 0 | BM17: =COUNTIF($E17:$AA17,BM$4) -> 0 | BN17: =COUNTIF($E17:$AA17,BN$4) -> 0 | BO17: =COUNTIF($E17:$AA17,BO$4) -> 2
B18: CFC MOK CHENGXUN | D18: DM | F18: DM | H18: AMPT | O18: DM | R18: DM | V18: MA | AB18: MA | AC18: DM | AP18: =SUMPRODUCT(--WEEKDAY(C$3:AG$3,2)<6,--((C18:AG18="DM"))+(C18:AG18="CS1")+((C18:AG18="CS2"))+(C18:AG18="SB1")+(C18:AG18="AE")+(C18:AG18="EM")) -> 0 | AR18: =SUMPRODUCT(--WEEKDAY(C$3:AG$3,2)>5,--((C18:AG18="DM"))+(C18:AG18="CS1")+((C18:AG18="CS2"))+(C18:AG18="SB1")+(C18:AG18="AE")+(C18:AG18="EM")) -> 0 | AT18: =(AP18-AQ18)/2+(AR18-AS18) -> 0 | AU18: =AH18+AI18+AJ18+AK18+AM18+AN18 -> 0 | AV18: =BF18+BG18+BI18+BD18+BB18+AZ18+BK18 -> 0 | AW18: =AT18+AX18 -> #VALUE! | AX18: =(BI18*('Setting key Duty'!$I$8+'Setting key Duty'!$I$12))+(BG18*'Setting key Duty'!$I$9)+(BB18*('Setting key Duty'!$I$13+'Setting key Duty'!$I$9))+(AZ18*('Setting key Duty'!$I$13+'Setting key Duty'!$I$12+'Setting key Duty'!$I$11))+(BD18*('Setting key Duty'!$I$8+'Setting key Duty'!$I$9+'Setting key Duty'!$I$12)) -> #VALUE! | AY18: =COUNTIF(C18:AC18,"*BRT*") -> 0 | AZ18: =COUNTIF(A18:AH18,"*$BTP*") -> 0 | BA18: =AZ18*('Setting key Duty'!$I$13+'Setting key Duty'!$I$12+'Setting key Duty'!$I$11) -> #VALUE! | BB18: =COUNTIF(A18:AH18,"*$L*") -> 0 | BC18: =BB18*('Setting key Duty'!$I$13+'Setting key Duty'!$I$9) -> #VALUE! | BD18: =COUNTIF(A18:AH18,"*$M*") -> 0 | BE18: =BD18*('Setting key Duty'!$I$8+'Setting key Duty'!$I$9+'Setting key Duty'!$I$12) -> 0 | BF18: =COUNTIF(AH18,"*$N*") -> 0 | BG18: =COUNTIF(AH18,"*$PM*") -> 0 | BH18: =BG18*('Setting key Duty'!$I$9) -> 0 | BI18: =COUNTIF(A18:AH18,"*$AM*") -> 0 | BJ18: =BI18*('Setting key Duty'!$I$12+'Setting key Duty'!$I$8) -> 0 | BK18: =COUNTIF(C18:AH18,"*$FC*") -> 0 | BL18: =BK18*('Setting key Duty'!$J$11+'Setting key Duty'!$I$8) -> 0 | BM18: =COUNTIF($C18:$AC18,BM$4) -> 0 | BN18: =COUNTIF($C18:$AC18,BN$4) -> 0 | BO18: =COUNTIF($C18:$AC18,BO$4) -> 0
B19: CPL PANG JUN YUAN | C19: DM | F19: CS2 | I19: DM | L19: SB1 | O19: CS2 | Q19: AL | T19: CS1 | Y19: DM | AB19: CS2 | AD19: AL | AP19: =SUMPRODUCT(--WEEKDAY(C$3:AG$3,2)<6,--((C19:AG19="DM"))+(C19:AG19="CS1")+((C19:AG19="CS2"))+(C19:AG19="SB1")+(C19:AG19="AE")+(C19:AG19="EM")) -> 0 | AR19: =SUMPRODUCT(--WEEKDAY(C$3:AG$3,2)>5,--((C19:AG19="DM"))+(C19:AG19="CS1")+((C19:AG19="CS2"))+(C19:AG19="SB1")+(C19:AG19="AE")+(C19:AG19="EM")) -> 0 | AT19: =(AP19-AQ19)/2+(AR19-AS19) -> 0 | AU19: =AH19+AI19+AJ19+AK19+AM19+AN19 -> 0 | AV19: =BF19+BG19+BI19+BD19+BB19+AZ19+BK19 -> 0 | AW19: =AT19+AX19 -> #VALUE! | AX19: =(BI19*('Setting key Duty'!$I$8+'Setting key Duty'!$I$12))+(BG19*'Setting key Duty'!$I$9)+(BB19*('Setting key Duty'!$I$13+'Setting key Duty'!$I$9))+(AZ19*('Setting key Duty'!$I$13+'Setting key Duty'!$I$12+'Setting key Duty'!$I$11))+(BD19*('Setting key Duty'!$I$8+'Setting key Duty'!$I$9+'Setting key Duty'!$I$12)) -> #VALUE! | AY19: =COUNTIF(D19:AC19,"*BRT*") -> 0 | AZ19: =COUNTIF(A19:AH19,"*$BTP*") -> 0 | BA19: =AZ19*('Setting key Duty'!$I$13+'Setting key Duty'!$I$12+'Setting key Duty'!$I$11) -> #VALUE! | BB19: =COUNTIF(A19:AH19,"*$L*") -> 0 | BC19: =BB19*('Setting key Duty'!$I$13+'Setting key Duty'!$I$9) -> #VALUE! | BD19: =COUNTIF(A19:AH19,"*$M*") -> 0 | BE19: =BD19*('Setting key Duty'!$I$8+'Setting key Duty'!$I$9+'Setting key Duty'!$I$12) -> 0 | BF19: =COUNTIF(AF19:AH19,"*$N*") -> 0 | BG19: =COUNTIF(AF19:AH19,"*$PM*") -> 0 | BH19: =BG19*('Setting key Duty'!$I$9) -> 0 | BI19: =COUNTIF(A19:AH19,"*$AM*") -> 0 | BJ19: =BI19*('Setting key Duty'!$I$12+'Setting key Duty'!$I$8) -> 0 | BK19: =COUNTIF(D19:AH19,"*$FC*") -> 0 | BL19: =BK19*('Setting key Duty'!$J$11+'Setting key Duty'!$I$8) -> 0 | BM19: =COUNTIF($D19:$AE19,BM$4) -> 0 | BN19: =COUNTIF($D19:$AE19,BN$4) -> 0 | BO19: =COUNTIF($D19:$AE19,BO$4) -> 2
B20: LCP SEE WEI ZHI | C20: OL | D20: OL | E20: OL | F20: SB1 | H20: AMPT | K20: SB1 | O20: CS1 | R20: CS1 | T20: DM | W20: DM | Y20: AL | Z20: AL | AA20: AL | AB20: AL | AC20: AL | AD20: AL | AE20: AL | AF20: AL | AG20: AL | AP20: =SUMPRODUCT(--WEEKDAY(C$3:AG$3,2)<6,--((C20:AG20="DM"))+(C20:AG20="CS1")+((C20:AG20="CS2"))+(C20:AG20="SB1")+(C20:AG20="AE")+(C20:AG20="EM")) -> 0 | AR20: =SUMPRODUCT(--WEEKDAY(C$3:AG$3,2)>5,--((C20:AG20="DM"))+(C20:AG20="CS1")+((C20:AG20="CS2"))+(C20:AG20="SB1")+(C20:AG20="AE")+(C20:AG20="EM")) -> 0 | AT20: =(AP20-AQ20)/2+(AR20-AS20) -> 0 | AU20: =AH20+AI20+AJ20+AK20+AM20+AN20 -> 0 | AV20: =BF20+BG20+BI20+BD20+BB20+AZ20+BK20 -> 0 | AW20: =AT20+AX20 -> #VALUE! | AX20: =(BI20*('Setting key Duty'!$I$8+'Setting key Duty'!$I$12))+(BG20*'Setting key Duty'!$I$9)+(BB20*('Setting key Duty'!$I$13+'Setting key Duty'!$I$9))+(AZ20*('Setting key Duty'!$I$13+'Setting key Duty'!$I$12+'Setting key Duty'!$I$11))+(BD20*('Setting key Duty'!$I$8+'Setting key Duty'!$I$9+'Setting key Duty'!$I$12)) -> #VALUE! | AY20: =COUNTIF(D20:AB20,"*BRT*") -> 0 | AZ20: =COUNTIF(A20:AH20,"*$BTP*") -> 0 | BA20: =AZ20*('Setting key Duty'!$I$13+'Setting key Duty'!$I$12+'Setting key Duty'!$I$11) -> #VALUE! | BB20: =COUNTIF(A20:AH20,"*$L*") -> 0 | BC20: =BB20*('Setting key Duty'!$I$13+'Setting key Duty'!$I$9) -> #VALUE! | BD20: =COUNTIF(A20:AH20,"*$M*") -> 0 | BE20: =BD20*('Setting key Duty'!$I$8+'Setting key Duty'!$I$9+'Setting key Duty'!$I$12) -> 0 | BF20: =COUNTIF(AF20:AH20,"*$N*") -> 0 | BG20: =COUNTIF(AF20:AH20,"*$PM*") -> 0 | BH20: =BG20*('Setting key Duty'!$I$9) -> 0 | BI20: =COUNTIF(A20:AH20,"*$AM*") -> 0 | BJ20: =BI20*('Setting key Duty'!$I$12+'Setting key Duty'!$I$8) -> 0 | BK20: =COUNTIF(D20:AH20,"*$FC*") -> 0 | BL20: =BK20*('Setting key Duty'!$J$11+'Setting key Duty'!$I$8) -> 0 | BM20: =COUNTIF($D20:$AE20,BM$4) -> 0 | BN20: =COUNTIF($D20:$AE20,BN$4) -> 0 | BO20: =COUNTIF($D20:$AE20,BO$4) -> 7
A21: AL | B21: LCP ESWARAN SENTHILKUMAR | C21: AL | D21: AL | E21: AL | F21: AL | G21: CS1 | J21: CS2 | N21: DM | S21: DM | W21: CS2 | Z21: CS2 | AB21: MC | AC21: MC | AP21: =SUMPRODUCT(--WEEKDAY(C$3:AG$3,2)<6,--((C21:AG21="DM"))+(C21:AG21="CS1")+((C21:AG21="CS2"))+(C21:AG21="SB1")+(C21:AG21="AE")+(C21:AG21="EM")) -> 0 | AR21: =SUMPRODUCT(--WEEKDAY(C$3:AG$3,2)>5,--((C21:AG21="DM"))+(C21:AG21="CS1")+((C21:AG21="CS2"))+(C21:AG21="SB1")+(C21:AG21="AE")+(C21:AG21="EM")) -> 0 | AT21: =(AP21-AQ21)/2+(AR21-AS21) -> 0 | AU21: =AH21+AI21+AJ21+AK21+AM21+AN21 -> 0 | AV21: =BF21+BG21+BI21+BD21+BB21+AZ21+BK21 -> 0 | AW21: =AT21+AX21 -> #VALUE! | AX21: =(BI21*('Setting key Duty'!$I$8+'Setting key Duty'!$I$12))+(BG21*'Setting key Duty'!$I$9)+(BB21*('Setting key Duty'!$I$13+'Setting key Duty'!$I$9))+(AZ21*('Setting key Duty'!$I$13+'Setting key Duty'!$I$12+'Setting key Duty'!$I$11))+(BD21*('Setting key Duty'!$I$8+'Setting key Duty'!$I$9+'Setting key Duty'!$I$12)) -> #VALUE! | AY21: =COUNTIF(D21:AC21,"*BRT*") -> 0 | AZ21: =COUNTIF(A21:AH21,"*$BTP*") -> 0 | BA21: =AZ21*('Setting key Duty'!$I$13+'Setting key Duty'!$I$12+'Setting key Duty'!$I$11) -> #VALUE! | BB21: =COUNTIF(A21:AH21,"*$L*") -> 0 | BC21: =BB21*('Setting key Duty'!$I$13+'Setting key Duty'!$I$9) -> #VALUE! | BD21: =COUNTIF(A21:AH21,"*$M*") -> 0 | BE21: =BD21*('Setting key Duty'!$I$8+'Setting key Duty'!$I$9+'Setting key Duty'!$I$12) -> 0 | BF21: =COUNTIF(AH21,"*$N*") -> 0 | BG21: =COUNTIF(AH21,"*$PM*") -> 0 | BH21: =BG21*('Setting key Duty'!$I$9) -> 0 | BI21: =COUNTIF(A21:AH21,"*$AM*") -> 0 | BJ21: =BI21*('Setting key Duty'!$I$12+'Setting key Duty'!$I$8) -> 0 | BK21: =COUNTIF(D21:AH21,"*$FC*") -> 0 | BL21: =BK21*('Setting key Duty'!$J$11+'Setting key Duty'!$I$8) -> 0 | BM21: =COUNTIF($D21:$AC21,BM$4) -> 0 | BN21: =COUNTIF($D21:$AC21,BN$4) -> 0 | BO21: =COUNTIF($D21:$AC21,BO$4) -> 3
B22: CFC TAN WAI KEAT | D22: CS1 | G22: DM | I22: CS2 | K22: AL | L22: AL | M22: AL | N22: AL | O22: AL | P22: AL | Q22: AL | R22: AL | S22: AL | T22: AL | U22: AL | V22: AL | W22: AL | X22: DM | AA22: SB1 | AC22: CS1 | AP22: =SUMPRODUCT(--WEEKDAY(C$3:AG$3,2)<6,--((C22:AG22="DM"))+(C22:AG22="CS1")+((C22:AG22="CS2"))+(C22:AG22="SB1")+(C22:AG22="AE")+(C22:AG22="EM")) -> 0 | AR22: =SUMPRODUCT(--WEEKDAY(C$3:AG$3,2)>5,--((C22:AG22="DM"))+(C22:AG22="CS1")+((C22:AG22="CS2"))+(C22:AG22="SB1")+(C22:AG22="AE")+(C22:AG22="EM")) -> 0 | AT22: =(AP22-AQ22)/2+(AR22-AS22) -> 0 | AU22: =AH22+AI22+AJ22+AK22+AM22+AN22 -> 0 | AV22: =BF22+BG22+BI22+BD22+BB22+AZ22+BK22 -> 0 | AW22: =AT22+AX22 -> #VALUE! | AX22: =(BI22*('Setting key Duty'!$I$8+'Setting key Duty'!$I$12))+(BG22*'Setting key Duty'!$I$9)+(BB22*('Setting key Duty'!$I$13+'Setting key Duty'!$I$9))+(AZ22*('Setting key Duty'!$I$13+'Setting key Duty'!$I$12+'Setting key Duty'!$I$11))+(BD22*('Setting key Duty'!$I$8+'Setting key Duty'!$I$9+'Setting key Duty'!$I$12)) -> #VALUE! | AY22: =COUNTIF(D22:AC22,"*BRT*") -> 0 | AZ22: =COUNTIF(A22:AH22,"*$BTP*") -> 0 | BA22: =AZ22*('Setting key Duty'!$I$13+'Setting key Duty'!$I$12+'Setting key Duty'!$I$11) -> #VALUE! | BB22: =COUNTIF(A22:AH22,"*$L*") -> 0 | BC22: =BB22*('Setting key Duty'!$I$13+'Setting key Duty'!$I$9) -> #VALUE! | BD22: =COUNTIF(A22:AH22,"*$M*") -> 0 | BE22: =BD22*('Setting key Duty'!$I$8+'Setting key Duty'!$I$9+'Setting key Duty'!$I$12) -> 0 | BF22: =COUNTIF(AE22:AH22,"*$N*") -> 0 | BG22: =COUNTIF(AE22:AH22,"*$PM*") -> 0 | BH22: =BG22*('Setting key Duty'!$I$9) -> 0 | BI22: =COUNTIF(A22:AH22,"*$AM*") -> 0 | BJ22: =BI22*('Setting key Duty'!$I$12+'Setting key Duty'!$I$8) -> 0 | BK22: =COUNTIF(D22:AH22,"*$FC*") -> 0 | BL22: =BK22*('Setting key Duty'!$J$11+'Setting key Duty'!$I$8) -> 0 | BM22: =COUNTIF($D22:$AE22,BM$4) -> 0 | BN22: =COUNTIF($D22:$AE22,BN$4) -> 0 | BO22: =COUNTIF($D22:$AE22,BO$4) -> 13
B23: LCP WAN FARID BIN ABDULLAH | C23: AL | F23: K $FC | G23: K $FC | H23: K $FC | I23: K $FC | M23: CS2 | O23: AE | S23: CS1 | W23: R $M 12KM RM (1600-2359) | Y23: CS2 | AC23: H $M RE 12 KM RM (1700 - 2359) | AF23: CS1 | AP23: =SUMPRODUCT(--WEEKDAY(C$3:AG$3,2)<6,--((C23:AG23="DM"))+(C23:AG23="CS1")+((C23:AG23="CS2"))+(C23:AG23="SB1")+(C23:AG23="AE")+(C23:AG23="EM")) -> 0 | AR23: =SUMPRODUCT(--WEEKDAY(C$3:AG$3,2)>5,--((C23:AG23="DM"))+(C23:AG23="CS1")+((C23:AG23="CS2"))+(C23:AG23="SB1")+(C23:AG23="AE")+(C23:AG23="EM")) -> 0 | AT23: =(AP23-AQ23)/2+(AR23-AS23) -> 0 | AU23: =AH23+AI23+AJ23+AK23+AM23+AN23 -> 0 | AV23: =BF23+BG23+BI23+BD23+BB23+AZ23+BK23 -> 6 | AW23: =AT23+AX23 -> #VALUE! | AX23: =(BI23*('Setting key Duty'!$I$8+'Setting key Duty'!$I$12))+(BG23*'Setting key Duty'!$I$9)+(BB23*('Setting key Duty'!$I$13+'Setting key Duty'!$I$9))+(AZ23*('Setting key Duty'!$I$13+'Setting key Duty'!$I$12+'Setting key Duty'!$I$11))+(BD23*('Setting key Duty'!$I$8+'Setting key Duty'!$I$9+'Setting key Duty'!$I$12)) -> #VALUE! | AY23: =COUNTIF(D23:AA23,"*BRT*") -> 0 | AZ23: =COUNTIF(A23:AH23,"*$BTP*") -> 0 | BA23: =AZ23*('Setting key Duty'!$I$13+'Setting key Duty'!$I$12+'Setting key Duty'!$I$11) -> #VALUE! | BB23: =COUNTIF(A23:AH23,"*$L*") -> 0 | BC23: =BB23*('Setting key Duty'!$I$13+'Setting key Duty'!$I$9) -> #VALUE! | BD23: =COUNTIF(A23:AH23,"*$M*") -> 2 | BE23: =BD23*('Setting key Duty'!$I$8+'Setting key Duty'!$I$9+'Setting key Duty'!$I$12) -> 1.125 | BF23: =COUNTIF(AH23,"*$N*") -> 0 | BG23: =COUNTIF(AH23,"*$PM*") -> 0 | BH23: =BG23*('Setting key Duty'!$I$9) -> 0 | BI23: =COUNTIF(A23:AH23,"*$AM*") -> 0 | BJ23: =BI23*('Setting key Duty'!$I$12+'Setting key Duty'!$I$8) -> 0 | BK23: =COUNTIF(D23:AH23,"*$FC*") -> 4 | BL23: =BK23*('Setting key Duty'!$J$11+'Setting key Duty'!$I$8) -> 0.5 | BM23: =COUNTIF($D23:$AA23,BM$4) -> 0 | BN23: =COUNTIF($D23:$AA23,BN$4) -> 0 | BO23: =COUNTIF($D23:$AA23,BO$4) -> 0
B24: PTE JAY DEOL FROST | D24: D $FC | E24: D $FC | F24: D $FC | G24: D $FC | H24: D $FC | J24: SB2 | N24: R $PM PERSMTAFF SOC (1530 -2000) | Q24: O $FC | R24: O $FC | S24: O $FC | T24: O $FC | U24: OFF | V24: L $PM ER (1530-2000) | W24: H $M 12KM RM (1400-2359) | Z24: SB1 | AD24: MC | AH24: =COUNTIF($C24:$AF24,AH$4) -> 0 | AI24: =COUNTIF($C24:$AF24,AI$4) -> 0 | AJ24: =COUNTIF($C24:$AF24,AJ$4) -> 0 | AK24: =COUNTIF($C24:$AF24,AK$4) -> 1 | AL24: =COUNTIF($C24:$AF24,AL$4) -> 1 | AM24: =COUNTIF($C24:$AF24,AM$4) -> 0 | AN24: =COUNTIF($C24:$AF24,AN$4) -> 0 | AP24: =SUMPRODUCT(--WEEKDAY(C$3:AG$3,2)<6,--((C24:AG24="DM"))+(C24:AG24="CS1")+((C24:AG24="CS2"))+(C24:AG24="SB1")+(C24:AG24="AE")+(C24:AG24="EM")) -> 0 | AR24: =SUMPRODUCT(--WEEKDAY(C$3:AG$3,2)>5,--((C24:AG24="DM"))+(C24:AG24="CS1")+((C24:AG24="CS2"))+(C24:AG24="SB1")+(C24:AG24="AE")+(C24:AG24="EM")) -> 0 | AT24: =(AP24-AQ24)/2+(AR24-AS24) -> 0 | AU24: =AH24+AI24+AJ24+AK24+AM24+AN24 -> 1 | AV24: =BF24+BG24+BI24+BD24+BB24+AZ24+BK24 -> 12 | AW24: =AT24+AX24 -> #VALUE! | AX24: =(BI24*('Setting key Duty'!$I$8+'Setting key Duty'!$I$12))+(BG24*'Setting key Duty'!$I$9)+(BB24*('Setting key Duty'!$I$13+'Setting key Duty'!$I$9))+(AZ24*('Setting key Duty'!$I$13+'Setting key Duty'!$I$12+'Setting key Duty'!$I$11))+(BD24*('Setting key Duty'!$I$8+'Setting key Duty'!$I$9+'Setting key Duty'!$I$12)) -> #VALUE! | AY24: =COUNTIF(C24:AC24,"*BRT*") -> 0 | AZ24: =COUNTIF(A24:AH24,"*$BTP*") -> 0 | BA24: =AZ24*('Setting key Duty'!$I$13+'Setting key Duty'!$I$12+'Setting key Duty'!$I$11) -> #VALUE! | BB24: =COUNTIF(I24:AH24,"*$L*") -> 0 | BC24: =BB24*('Setting key Duty'!$I$13+'Setting key Duty'!$I$9) -> #VALUE! | BD24: =COUNTIF(I24:AH24,"*$M*") -> 1 | BE24: =BD24*('Setting key Duty'!$I$8+'Setting key Duty'!$I$9+'Setting key Duty'!$I$12) -> 0.5625 | BF24: =COUNTIF(I24:AH24,"*$N*") -> 0 | BG24: =COUNTIF(I24:AH24,"*$PM*") -> 2 | BH24: =BG24*('Setting key Duty'!$I$9) -> 0.25 | BI24: =COUNTIF(I24:AH24,"*$AM*") -> 0 | BJ24: =BI24*('Setting key Duty'!$I$12+'Setting key Duty'!$I$8) -> 0 | BK24: =COUNTIF(C24:AH24,"*$FC*") -> 9 | BL24: =BK24*('Setting key Duty'!$J$11+'Setting key Duty'!$I$8) -> 1.125 | BM24: =COUNTIF($C24:$AF24,BM$4) -> 0 | BN24: =COUNTIF($C24:$AF24,BN$4) -> 0 | BO24: =COUNTIF($I24:$AE24,BO$4) -> 0
B25: LCP MUHAMMAD AQIL HAMZAH BIN SYELDRICK | C25: O $BTP (0530-2359) | F25: AE | G25: SB2 | I25: C $AM 8KM (0600-1100) | J25: HQ NSMEN $AM IPPT (0530-1000) | M25: R $AM 8KM (0600-1000) | P25: C $AM IPPT (0500-1100) | Q25: HQ NSMEN $AM IPPT (0530-1000) | S25: SB1 | V25: F $M 12 KM RM (1400-2359) | W25: N $AM IPPT (0500-1100) | X25: SB2 | AA25: AE | AC25: N $M ISAD (0530-2000) | AP25: =SUMPRODUCT(--WEEKDAY(C$3:AG$3,2)<6,--((C25:AG25="DM"))+(C25:AG25="CS1")+((C25:AG25="CS2"))+(C25:AG25="SB1")+(C25:AG25="AE")+(C25:AG25="EM")) -> 0 | AR25: =SUMPRODUCT(--WEEKDAY(C$3:AG$3,2)>5,--((C25:AG25="DM"))+(C25:AG25="CS1")+((C25:AG25="CS2"))+(C25:AG25="SB1")+(C25:AG25="AE")+(C25:AG25="EM")) -> 0 | AT25: =(AP25-AQ25)/2+(AR25-AS25) -> 0 | AU25: =AH25+AI25+AJ25+AK25+AM25+AN25 -> 0 | AV25: =BF25+BG25+BI25+BD25+BB25+AZ25+BK25 -> 9 | AW25: =AT25+$AX$25 -> #VALUE! | AX25: =(BI25*('Setting key Duty'!$I$8+'Setting key Duty'!$I$12))+(BG25*'Setting key Duty'!$I$9)+(BB25*('Setting key Duty'!$I$13+'Setting key Duty'!$I$9))+(AZ25*('Setting key Duty'!$I$13+'Setting key Duty'!$I$12+'Setting key Duty'!$I$11))+(BD25*('Setting key Duty'!$I$8+'Setting key Duty'!$I$9+'Setting key Duty'!$I$12)) -> #VALUE! | AY25: =COUNTIF(C25:AC25,"*BRT*") -> 0 | AZ25: =COUNTIF(A25:AH25,"*$BTP*") -> 1 | BA25: =AZ25*('Setting key Duty'!$I$13+'Setting key Duty'!$I$12+'Setting key Duty'!$I$11) -> #VALUE! | BB25: =COUNTIF(D25:AH25,"*$L*") -> 0 | BC25: =BB25*('Setting key Duty'!$I$13+'Setting key Duty'!$I$9) -> #VALUE! | BD25: =COUNTIF(D25:AH25,"*$M*") -> 2 | BE25: =BD25*('Setting key Duty'!$I$8+'Setting key Duty'!$I$9+'Setting key Duty'!$I$12) -> 1.125 | BF25: =COUNTIF(D25:AH25,"*$N*") -> 0 | BG25: =COUNTIF(D25:AH25,"*$PM*") -> 0 | BH25: =BG25*('Setting key Duty'!$I$9) -> 0 | BI25: =COUNTIF(D25:AH25,"*$AM*") -> 6 | BJ25: =BI25*('Setting key Duty'!$I$12+'Setting key Duty'!$I$8) -> 2.625 | BK25: =COUNTIF(C25:AH25,"*$FC*") -> 0 | BL25: =BK25*('Setting key Duty'!$J$11+'Setting key Duty'!$I$8) -> 0 | BM25: =COUNTIF($C25:$AG25,BM$4) -> 0 | BN25: =COUNTIF($C25:$AG25,BN$4) -> 0 | BO25: =COUNTIF($D25:$AE25,BO$4) -> 0
B26: PTE JASON TAN JIAN CHEN | C26: AL | D26: AL | E26: AL | F26: AL | H26: L $M BIC (0530-2000) | I26: F $AM 8KM (0600-1100) | J26: L $AM 8KM (0600-1100) | M26: K $M HG (0530-2000) | N26: SB2 | O26: O $PM ER (1530 - 20000) | P26: K $BTP (0530 -2359) | Q26: SB2 | T26: SB2 | U26: C $M RE-IFC (0600-1500) | V26: R $AM IPPT (0530-1000) | W26: L $M 12KM RM (1400-2359) | X26: AL | AA26: OFF | AB26: H $M RE IFC (0700-1400) | AD26: AE | AP26: =SUMPRODUCT(--WEEKDAY(C$3:AG$3,2)<6,--((C26:AG26="DM"))+(C26:AG26="CS1")+((C26:AG26="CS2"))+(C26:AG26="SB1")+(C26:AG26="AE")+(C26:AG26="EM")) -> 0 | AR26: =SUMPRODUCT(--WEEKDAY(C$3:AG$3,2)>5,--((C26:AG26="DM"))+(C26:AG26="CS1")+((C26:AG26="CS2"))+(C26:AG26="SB1")+(C26:AG26="AE")+(C26:AG26="EM")) -> 0 | AT26: =(AP26-AQ26)/2+(AR26-AS26) -> 0 | AU26: =AH26+AI26+AJ26+AK26+AM26+AN26 -> 0 | AV26: =BF26+BG26+BI26+BD26+BB26+AZ26+BK26 -> 0 | AW26: =AT26+$AX$25 -> #VALUE! | AX26: =(BI26*('Setting key Duty'!$I$8+'Setting key Duty'!$I$12))+(BG26*'Setting key Duty'!$I$9)+(BB26*('Setting key Duty'!$I$13+'Setting key Duty'!$I$9))+(AZ26*('Setting key Duty'!$I$13+'Setting key Duty'!$I$12+'Setting key Duty'!$I$11))+(BD26*('Setting key Duty'!$I$8+'Setting key Duty'!$I$9+'Setting key Duty'!$I$12)) -> #VALUE!
B27: PTE MUHAMAD LUTFIL AL-HADI | C27: SB2 | E27: AE | G27: AE | I27: SB2 | K27: AE | M27: AE | P27: AE | R27: AE | U27: AE | V27: SB2 | W27: AE | Y27: WEDDING | AC27: SB2 | AD27: SB2 | AE27: AE | AP27: =SUMPRODUCT(--WEEKDAY(C$3:AG$3,2)<6,--((C27:AG27="DM"))+(C27:AG27="CS1")+((C27:AG27="CS2"))+(C27:AG27="SB1")+(C27:AG27="AE")+(C27:AG27="EM")) -> 0 | AR27: =SUMPRODUCT(--WEEKDAY(C$3:AG$3,2)>5,--((C27:AG27="DM"))+(C27:AG27="CS1")+((C27:AG27="CS2"))+(C27:AG27="SB1")+(C27:AG27="AE")+(C27:AG27="EM")) -> 0 | AT27: =(AP27-AQ27)/2+(AR27-AS27) -> 0 | AU27: =AH27+AI27+AJ27+AK27+AM27+AN27 -> 0 | AV27: =BF27+BG27+BI27+BD27+BB27+AZ27+BK27 -> 0 | AW27: =AT27+$AX$25 -> #VALUE! | AX27: =(BI27*('Setting key Duty'!$I$8+'Setting key Duty'!$I$12))+(BG27*'Setting key Duty'!$I$9)+(BB27*('Setting key Duty'!$I$13+'Setting key Duty'!$I$9))+(AZ27*('Setting key Duty'!$I$13+'Setting key Duty'!$I$12+'Setting key Duty'!$I$11))+(BD27*('Setting key Duty'!$I$8+'Setting key Duty'!$I$9+'Setting key Duty'!$I$12)) -> #VALUE!
B28: PTE JARRETT TSING KEE JIN | C28: AL | D28: AL | E28: AL | F28: L $PM ER (1530-2000) | G28: F $M BIC (0530 -2000) | I28: AE | L28: AE | N28: D $AM 8KM (0600-1100) | P28: SB2 | Q28: K $BTP (0530 -2359) | T28: OFF | U28: K $PM ER (1530-2000) | V28: K $M BIC (0530-2000) | W28: SB2 | X28: F $AM RE-IPPT (0500-1100) | Y28: AE | AB28: SB2 | AC28: O $M HG (0530-2000) | AD28: OFF | AE28: COURSE | AP28: =SUMPRODUCT(--WEEKDAY(C$3:AG$3,2)<6,--((C28:AG28="DM"))+(C28:AG28="CS1")+((C28:AG28="CS2"))+(C28:AG28="SB1")+(C28:AG28="AE")+(C28:AG28="EM")) -> 0 | AR28: =SUMPRODUCT(--WEEKDAY(C$3:AG$3,2)>5,--((C28:AG28="DM"))+(C28:AG28="CS1")+((C28:AG28="CS2"))+(C28:AG28="SB1")+(C28:AG28="AE")+(C28:AG28="EM")) -> 0 | AT28: =(AP28-AQ28)/2+(AR28-AS28) -> 0 | AU28: =AH28+AI28+AJ28+AK28+AM28+AN28 -> 0 | AV28: =BF28+BG28+BI28+BD28+BB28+AZ28+BK28 -> 0 | AW28: =AT28+$AX$25 -> #VALUE! | AX28: =(BI28*('Setting key Duty'!$I$8+'Setting key Duty'!$I$12))+(BG28*'Setting key Duty'!$I$9)+(BB28*('Setting key Duty'!$I$13+'Setting key Duty'!$I$9))+(AZ28*('Setting key Duty'!$I$13+'Setting key Duty'!$I$12+'Setting key Duty'!$I$11))+(BD28*('Setting key Duty'!$I$8+'Setting key Duty'!$I$9+'Setting key Duty'!$I$12)) -> #VALUE!
B29: PTE CHEN DENG FENG | F29: EXAM | G29: EXAM | H29: EXAM | I29: EXAM | J29: EXAM | M29: EXAM | N29: L $AM ER (0600-1100) | O29: SB2 | P29: L $AM IPPT (0500-1100) | Q29: F $AM IPPT (0500-1100) | T29: AL | U29: EXAM | V29: EXAM | W29: OFF | X29: EXAM | AA29: SB2 | AC29: EXAM | AE29: N $AM IPPT (0500-1100) | AG29: AE | AP29: =SUMPRODUCT(--WEEKDAY(C$3:AG$3,2)<6,--((C29:AG29="DM"))+(C29:AG29="CS1")+((C29:AG29="CS2"))+(C29:AG29="SB1")+(C29:AG29="AE")+(C29:AG29="EM")) -> 0 | AR29: =SUMPRODUCT(--WEEKDAY(C$3:AG$3,2)>5,--((C29:AG29="DM"))+(C29:AG29="CS1")+((C29:AG29="CS2"))+(C29:AG29="SB1")+(C29:AG29="AE")+(C29:AG29="EM")) -> 0 | AT29: =(AP29-AQ29)/2+(AR29-AS29) -> 0 | AU29: =AH29+AI29+AJ29+AK29+AM29+AN29 -> 0 | AV29: =BF29+BG29+BI29+BD29+BB29+AZ29+BK29 -> 0 | AW29: =AT29+$AX$25 -> #VALUE! | AX29: =(BI29*('Setting key Duty'!$I$8+'Setting key Duty'!$I$12))+(BG29*'Setting key Duty'!$I$9)+(BB29*('Setting key Duty'!$I$13+'Setting key Duty'!$I$9))+(AZ29*('Setting key Duty'!$I$13+'Setting key Duty'!$I$12+'Setting key Duty'!$I$11))+(BD29*('Setting key Duty'!$I$8+'Setting key Duty'!$I$9+'Setting key Duty'!$I$12)) -> #VALUE!
B30: PTE MARK WU | C30: OFF | F30: OFF | H30: SB2 | I30: H $AM 8KM (0600-1100) | J30: AE | M30: SB2 | O30: D $M BIC (0530-2000) | Q30: D $M HG (0530-2000) | R30: WEDDING | S30: AE | T30: H $PM ER (1530-2000) | V30: H $PM IPPT (1530-2000) | W30: L $AM PERSMTAFF SOC(0540-1100) | Z30: AE | AB30: MC | AC30: MC | AD30: SCH1 $M HQ GP REHEARSAL(0800 - 1700) | AE30: OFF | AP30: =SUMPRODUCT(--WEEKDAY(C$3:AG$3,2)<6,--((C30:AG30="DM"))+(C30:AG30="CS1")+((C30:AG30="CS2"))+(C30:AG30="SB1")+(C30:AG30="AE")+(C30:AG30="EM")) -> 0 | AR30: =SUMPRODUCT(--WEEKDAY(C$3:AG$3,2)>5,--((C30:AG30="DM"))+(C30:AG30="CS1")+((C30:AG30="CS2"))+(C30:AG30="SB1")+(C30:AG30="AE")+(C30:AG30="EM")) -> 0 | AT30: =(AP30-AQ30)/2+(AR30-AS30) -> 0 | AU30: =AH30+AI30+AJ30+AK30+AM30+AN30 -> 0 | AV30: =BF30+BG30+BI30+BD30+BB30+AZ30+BK30 -> 0 | AW30: =AT30+$AX$25 -> #VALUE! | AX30: =(BI30*('Setting key Duty'!$I$8+'Setting key Duty'!$I$12))+(BG30*'Setting key Duty'!$I$9)+(BB30*('Setting key Duty'!$I$13+'Setting key Duty'!$I$9))+(AZ30*('Setting key Duty'!$I$13+'Setting key Duty'!$I$12+'Setting key Duty'!$I$11))+(BD30*('Setting key Duty'!$I$8+'Setting key Duty'!$I$9+'Setting key Duty'!$I$12)) -> #VALUE!
B31: PTE EUAN TING | C31: HQ NSMEN $AM IPPT (0530-1000) | D31: AE | F31: SB2 | H31: C $AM IPPT (0500-1100) | J31: F $AM IPPT (0500-1100) | M31: L $PM PERSMTAFF SOC (1530 -2000) | N31: AE | P31: D $AM IPPT (0500-1100) | Q31: AE | T31: AE | U31: SB2 | V31: D $M 12 KM RM (1400-2359) | X31: AE | AB31: C $M RE-12KM RM (1400-2359) | AC31: L $AM PERSMTAFF SOC(0600-1100) | AE31: SB2 | AF31: AE | AP31: =SUMPRODUCT(--WEEKDAY(C$3:AG$3,2)<6,--((C31:AG31="DM"))+(C31:AG31="CS1")+((C31:AG31="CS2"))+(C31:AG31="SB1")+(C31:AG31="AE")+(C31:AG31="EM")) -> 0 | AR31: =SUMPRODUCT(--WEEKDAY(C$3:AG$3,2)>5,--((C31:AG31="DM"))+(C31:AG31="CS1")+((C31:AG31="CS2"))+(C31:AG31="SB1")+(C31:AG31="AE")+(C31:AG31="EM")) -> 0 | AT31: =(AP31-AQ31)/2+(AR31-AS31) -> 0 | AU31: =AH31+AI31+AJ31+AK31+AM31+AN31 -> 0 | AV31: =BF31+BG31+BI31+BD31+BB31+AZ31+BK31 -> 0 | AW31: =AT31+$AX$25 -> #VALUE! | AX31: =(BI31*('Setting key Duty'!$I$8+'Setting key Duty'!$I$12))+(BG31*'Setting key Duty'!$I$9)+(BB31*('Setting key Duty'!$I$13+'Setting key Duty'!$I$9))+(AZ31*('Setting key Duty'!$I$13+'Setting key Duty'!$I$12+'Setting key Duty'!$I$11))+(BD31*('Setting key Duty'!$I$8+'Setting key Duty'!$I$9+'Setting key Duty'!$I$12)) -> #VALUE!
AP32: =SUMPRODUCT(--WEEKDAY(C$3:AG$3,2)<6,--((C32:AG32="DM"))+(C32:AG32="CS1")+((C32:AG32="CS2"))+(C32:AG32="SB1")+(C32:AG32="AE")+(C32:AG32="EM")) -> 0 | AR32: =SUMPRODUCT(--WEEKDAY(C$3:AG$3,2)>5,--((C32:AG32="DM"))+(C32:AG32="CS1")+((C32:AG32="CS2"))+(C32:AG32="SB1")+(C32:AG32="AE")+(C32:AG32="EM")) -> 0 | AT32: =(AP32-AQ32)/2+(AR32-AS32) -> 0 | AU32: =AH32+AI32+AJ32+AK32+AM32+AN32 -> 0 | AV32: =BF32+BG32+BI32+BD32+BB32+AZ32+BK32 -> 0 | AW32: =AT32+AX32 -> #VALUE! | AX32: =(BI32*('Setting key Duty'!$I$8+'Setting key Duty'!$I$12))+(BG32*'Setting key Duty'!$I$9)+(BB32*('Setting key Duty'!$I$13+'Setting key Duty'!$I$9))+(AZ32*('Setting key Duty'!$I$13+'Setting key Duty'!$I$12+'Setting key Duty'!$I$11))+(BD32*('Setting key Duty'!$I$8+'Setting key Duty'!$I$9+'Setting key Duty'!$I$12)) -> #VALUE! | AY32: =COUNTIF(C32:Y32,"*BRT*") -> 0 | AZ32: =COUNTIF(A32:AH32,"*$BTP*") -> 0 | BA32: =AZ32*('Setting key Duty'!$I$13+'Setting key Duty'!$I$12+'Setting key Duty'!$I$11) -> #VALUE! | BB32: =COUNTIF(D32:AH32,"*$L*") -> 0 | BC32: =BB32*('Setting key Duty'!$I$13+'Setting key Duty'!$I$9) -> #VALUE! | BD32: =COUNTIF(D32:AH32,"*$M*") -> 0 | BE32: =BD32*('Setting key Duty'!$I$8+'Setting key Duty'!$I$9+'Setting key Duty'!$I$12) -> 0 | BF32: =COUNTIF(D32:AH32,"*$N*") -> 0 | BG32: =COUNTIF(D32:AH32,"*$PM*") -> 0 | BH32: =BG32*('Setting key Duty'!$I$9) -> 0 | BI32: =COUNTIF(D32:AH32,"*$AM*") -> 0 | BJ32: =BI32*('Setting key Duty'!$I$12+'Setting key Duty'!$I$8) -> 0 | BK32: =COUNTIF(C32:AH32,"*$FC*") -> 0 | BL32: =BK32*('Setting key Duty'!$J$11+'Setting key Duty'!$I$8) -> 0 | BM32: =COUNTIF($C32:$AG32,BM$4) -> 0 | BN32: =COUNTIF($C32:$AG32,BN$4) -> 0 | BO32: =COUNTIF($D32:$AE32,BO$4) -> 0
B33: Leave a blank row after the last name ^ | AH33: =COUNTIF($C33:$AG33,AH$4) -> 0 | AI33: =COUNTIF($C33:$AG33,AI$4) -> 0 | AJ33: =COUNTIF($C33:$AG33,AJ$4) -> 0 | AK33: =COUNTIF($C33:$AG33,AK$4) -> 0 | AL33: =COUNTIF($C33:$AG33,AL$4) -> 0 | AM33: =COUNTIF($C33:$AG33,AM$4) -> 0 | AN33: =COUNTIF($C33:$AG33,AN$4) -> 0 | AP33: =SUMPRODUCT(--WEEKDAY(C$3:AG$3,2)<6,--((C33:AG33="DM"))+(C33:AG33="CS1")+((C33:AG33="CS2"))+(C33:AG33="SB1")+(C33:AG33="AE")+(C33:AG33="EM")) -> 0 | AR33: =SUMPRODUCT(--WEEKDAY(C$3:AG$3,2)>5,--((C33:AG33="DM"))+(C33:AG33="CS1")+((C33:AG33="CS2"))+(C33:AG33="SB1")+(C33:AG33="AE")+(C33:AG33="EM")) -> 0 | AT33: =(AP33-AQ33)/2+(AR33-AS33) -> 0 | AU33: =AH33+AI33+AJ33+AK33+AM33+AN33 -> 0 | AV33: =BF33+BG33+BI33+BD33+BB33+AZ33+BK33 -> 0 | AW33: =AT33+AX33 -> #VALUE! | AX33: =(BI33*('Setting key Duty'!$I$8+'Setting key Duty'!$I$12))+(BG33*'Setting key Duty'!$I$9)+(BB33*('Setting key Duty'!$I$13+'Setting key Duty'!$I$9))+(AZ33*('Setting key Duty'!$I$13+'Setting key Duty'!$I$12+'Setting key Duty'!$I$11))+(BD33*('Setting key Duty'!$I$8+'Setting key Duty'!$I$9+'Setting key Duty'!$I$12)) -> #VALUE! | AY33: =COUNTIF(C33:AG33,"*BRT*") -> 0 | AZ33: =COUNTIF(D33:AH33,"*$BTP*") -> 0 | BA33: =AZ33*('Setting key Duty'!$I$13+'Setting key Duty'!$I$12+'Setting key Duty'!$I$11) -> #VALUE! | BB33: =COUNTIF(D33:AH33,"*$L*") -> 0 | BC33: =BB33*('Setting key Duty'!$I$13+'Setting key Duty'!$I$9) -> #VALUE! | BD33: =COUNTIF(D33:AH33,"*$M*") -> 0 | BE33: =BD33*('Setting key Duty'!$I$8+'Setting key Duty'!$I$9+'Setting key Duty'!$I$12) -> 0 | BF33: =COUNTIF(D33:AH33,"*$N*") -> 0 | BG33: =COUNTIF(D33:AH33,"*$PM*") -> 0 | BH33: =BG33*('Setting key Duty'!$I$9) -> 0 | BI33: =COUNTIF(D33:AH33,"*$AM*") -> 0 | BJ33: =BI33*('Setting key Duty'!$I$12+'Setting key Duty'!$I$8) -> 0 | BK33: =COUNTIF(C33:AH33,"*$FC*") -> 0 | BL33: =BK33*('Setting key Duty'!$J$11+'Setting key Duty'!$I$8) -> 0 | BM33: =COUNTIF($C33:$AG33,BM$4) -> 0 | BN33: =COUNTIF($C33:$AG33,BN$4) -> 0 | BO33: =COUNTIF($C33:$AG33,BO$4) -> 0
AR34: =SUMPRODUCT(--WEEKDAY(C$3:AG$3,2)>5,--((C34:AG34="DM"))+(C34:AG34="CS1")+((C34:AG34="CS2"))+(C34:AG34="SB1")+(C34:AG34="AE")+(C34:AG34="EM")) -> 0 | AT34: =(AP34-AQ34)/2+(AR34-AS34) -> 0
B35: DM | C35: =VLOOKUP("DM",C4:C33,1,FALSE) -> DM | D35: =VLOOKUP("DM",D4:D33,1,FALSE) -> DM | E35: =VLOOKUP("DM",E4:E33,1,FALSE) -> DM | F35: =VLOOKUP("DM",F4:F33,1,FALSE) -> DM | G35: =VLOOKUP("DM",G4:G33,1,FALSE) -> DM | H35: =VLOOKUP("DM",H4:H33,1,FALSE) -> DM | I35: =VLOOKUP("DM",I4:I33,1,FALSE) -> DM | J35: =VLOOKUP("DM",J4:J33,1,FALSE) -> DM | ... L35: =VLOOKUP("DM",L4:L33,1,FALSE) -> DM | M35: =VLOOKUP("DM",M4:M32,1,FALSE) -> DM | N35: =VLOOKUP("DM",N4:N33,1,FALSE) -> DM | O35: =VLOOKUP("DM",O4:O33,1,FALSE) -> DM | P35: =VLOOKUP("DM",P4:P33,1,FALSE) -> DM | Q35: =VLOOKUP("DM",Q4:Q32,1,FALSE) -> DM | R35: =VLOOKUP("DM",R4:R31,1,FALSE) -> DM | S35: =VLOOKUP("DM",S4:S33,1,FALSE) -> DM | T35: =VLOOKUP("DM",T4:T33,1,FALSE) -> DM | U35: =VLOOKUP("DM",U4:U33,1,FALSE) -> DM | V35: =VLOOKUP("DM",V4:V30,1,FALSE) -> DM | W35: =VLOOKUP("DM",W4:W30,1,FALSE) -> DM | X35: =VLOOKUP("DM",X4:X33,1,FALSE) -> DM | Y35: =VLOOKUP("DM",Y4:Y33,1,FALSE) -> DM | Z35: =VLOOKUP("DM",Z4:Z33,1,FALSE) -> DM | AA35: =VLOOKUP("DM",AA5:AA33,1,FALSE) -> DM | AB35: =VLOOKUP("DM",AB4:AB33,1,FALSE) -> DM | AC35: =VLOOKUP("DM",AC4:AC33,1,FALSE) -> DM | AD35: =VLOOKUP("DM",AD4:AD33,1,FALSE) -> DM | AE35: =VLOOKUP("DM",AE4:AE33,1,FALSE) -> DM | AF35: =VLOOKUP("DM",AF4:AF33,1,FALSE) -> DM | AG35: =VLOOKUP("DM",AG4:AG33,1,FALSE) -> DM
A36: =LTE() -> #NAME? | B36: CS1 | C36: =VLOOKUP("CS1",C5:C33,1,FALSE) -> CS1 | D36: =VLOOKUP("CS1",D7:D33,1,FALSE) -> CS1 | E36: =VLOOKUP("CS1",E6:E33,1,FALSE) -> CS1 | F36: =VLOOKUP("CS1",F6:F33,1,FALSE) -> CS1 | G36: =VLOOKUP("CS1",G6:G33,1,FALSE) -> CS1 | H36: =VLOOKUP("CS1",H5:H33,1,FALSE) -> CS1 | I36: =VLOOKUP("CS1",I6:I33,1,FALSE) -> CS1 | J36: =VLOOKUP("CS1",J4:J33,1,FALSE) -> CS1 | K36: =VLOOKUP("CS1",K6:K33,1,FALSE) -> CS1 | L36: =VLOOKUP("CS1",L10:L33,1,FALSE) -> CS1 | M36: =VLOOKUP("CS1",M5:M32,1,FALSE) -> CS1 | N36: =VLOOKUP("CS1",N5:N33,1,FALSE) -> CS1 | O36: =VLOOKUP("CS1",O5:O33,1,FALSE) -> CS1 | P36: =VLOOKUP("CS1",P12:P33,1,FALSE) -> CS1 | Q36: =VLOOKUP("CS1",Q7:Q32,1,FALSE) -> CS1 | R36: =VLOOKUP("CS1",R6:R31,1,FALSE) -> CS1 | S36: =VLOOKUP("CS1",S5:S33,1,FALSE) -> CS1 | T36: =VLOOKUP("CS1",T6:T33,1,FALSE) -> CS1 | U36: =VLOOKUP("CS1",U7:U33,1,FALSE) -> CS1 | V36: =VLOOKUP("CS1",V7:V30,1,FALSE) -> CS1 | W36: =VLOOKUP("CS1",W1:W30,1,FALSE) -> CS1 | X36: =VLOOKUP("CS1",X1:X33,1,FALSE) -> CS1 | Y36: =VLOOKUP("CS1",Y5:Y33,1,FALSE) -> CS1 | Z36: =VLOOKUP("CS1",Z6:Z33,1,FALSE) -> CS1 | AA36: =VLOOKUP("CS1",AA5:AA33,1,FALSE) -> CS1 | AB36: =VLOOKUP("CS1",AB7:AB33,1,FALSE) -> CS1 | AC36: =VLOOKUP("CS1",AC6:AC33,1,FALSE) -> CS1 | AD36: =VLOOKUP("CS1",AD6:AD33,1,FALSE) -> CS1 | AE36: =VLOOKUP("CS1",AE6:AE33,1,FALSE) -> CS1 | AF36: =VLOOKUP("CS1",AF5:AF33,1,FALSE) -> CS1 | AG36: =VLOOKUP("CS1",AG6:AG33,1,FALSE) -> CS1
B37: CS2 | C37: =VLOOKUP("CS2",C6:C33,1,FALSE) -> CS2 | D37: =VLOOKUP("CS2",D7:D33,1,FALSE) -> CS2 | E37: =VLOOKUP("CS2",E6:E33,1,FALSE) -> CS2 | F37: =VLOOKUP("CS2",F6:F33,1,FALSE) -> CS2 | G37: =VLOOKUP("CS2",G6:G33,1,FALSE) -> CS2 | H37: =VLOOKUP("CS2",H6:H33,1,FALSE) -> CS2 | I37: =VLOOKUP("CS2",I6:I33,1,FALSE) -> CS2 | J37: =VLOOKUP("CS2",J4:J33,1,FALSE) -> CS2 | K37: =VLOOKUP("CS2",K6:K33,1,FALSE) -> CS2 | L37: =VLOOKUP("CS2",L4:L33,1,FALSE) -> CS2 | M37: =VLOOKUP("CS2",M6:M32,1,FALSE) -> CS2 | N37: =VLOOKUP("CS2",N5:N33,1,FALSE) -> CS2 | O37: =VLOOKUP("CS2",O10:O33,1,FALSE) -> CS2 | P37: =VLOOKUP("CS2",P6:P33,1,FALSE) -> CS2 | Q37: =VLOOKUP("CS2",Q7:Q32,1,FALSE) -> CS2 | R37: =VLOOKUP("CS2",R6:R31,1,FALSE) -> CS2 | S37: =VLOOKUP("CS2",S5:S33,1,FALSE) -> CS2 | T37: =VLOOKUP("CS2",T1:T33,1,FALSE) -> CS2 | U37: =VLOOKUP("CS2",U1:U33,1,FALSE) -> CS2 | V37: =VLOOKUP("CS2",V1:V30,1,FALSE) -> CS2 | W37: =VLOOKUP("CS2",W9:W30,1,FALSE) -> CS2 | X37: =VLOOKUP("CS2",X7:X33,1,FALSE) -> CS2 | Y37: =VLOOKUP("CS2",Y5:Y33,1,FALSE) -> CS2 | Z37: =VLOOKUP("CS2",Z6:Z33,1,FALSE) -> CS2 | AA37: =VLOOKUP("CS2",AA5:AA33,1,FALSE) -> CS2 | AB37: =VLOOKUP("CS2",AB1:AB33,1,FALSE) -> CS2 | AC37: =VLOOKUP("CS2",AC6:AC33,1,FALSE) -> CS2 | AD37: =VLOOKUP("CS2",AD6:AD33,1,FALSE) -> CS2 | AE37: =VLOOKUP("CS2",AE6:AE33,1,FALSE) -> CS2 | AF37: =VLOOKUP("CS2",AF5:AF33,1,FALSE) -> CS2 | AG37: =VLOOKUP("CS2",AG6:AG33,1,FALSE) -> CS2
B38: SB1 | C38: =VLOOKUP("SB1",C6:C33,1,FALSE) -> SB1 | D38: =VLOOKUP("SB1",D3:D33,1,FALSE) -> SB1 | E38: =VLOOKUP("SB1",E6:E33,1,FALSE) -> SB1 | F38: =VLOOKUP("SB1",F6:F33,1,FALSE) -> SB1 | G38: =VLOOKUP("SB1",G6:G33,1,FALSE) -> SB1 | H38: =VLOOKUP("SB1",H6:H33,1,FALSE) -> SB1 | I38: =VLOOKUP("SB1",I6:I33,1,FALSE) -> SB1 | J38: =VLOOKUP("SB1",J4:J33,1,FALSE) -> SB1 | K38: =VLOOKUP("SB1",K6:K33,1,FALSE) -> SB1 | L38: =VLOOKUP("SB1",L5:L33,1,FALSE) -> SB1 | M38: =VLOOKUP("SB1",M6:M32,1,FALSE) -> SB1 | N38: =VLOOKUP("SB1",N5:N33,1,FALSE) -> SB1 | O38: =VLOOKUP("SB1",O5:O33,1,FALSE) -> SB1 | P38: =VLOOKUP("SB1",P6:P33,1,FALSE) -> SB1 | Q38: =VLOOKUP("SB1",Q7:Q32,1,FALSE) -> SB1 | R38: =VLOOKUP("SB1",R6:R31,1,FALSE) -> SB1 | S38: =VLOOKUP("SB1",S5:S33,1,FALSE) -> SB1 | T38: =VLOOKUP("SB1",T6:T33,1,FALSE) -> SB1 | U38: =VLOOKUP("SB1",U7:U33,1,FALSE) -> SB1 | V38: =VLOOKUP("SB1",V6:V30,1,FALSE) -> SB1 | W38: =VLOOKUP("SB1",W9:W30,1,FALSE) -> SB1 | X38: =VLOOKUP("SB1",X7:X33,1,FALSE) -> #N/A | Y38: =VLOOKUP("SB1",Y5:Y33,1,FALSE) -> #N/A | Z38: =VLOOKUP("SB1",Z6:Z33,1,FALSE) -> SB1 | AA38: =VLOOKUP("SB1",AA5:AA33,1,FALSE) -> SB1 | AB38: =VLOOKUP("SB1",AB7:AB33,1,FALSE) -> SB1 | AC38: =VLOOKUP("SB1",AC1:AC33,1,FALSE) -> SB1 | AD38: =VLOOKUP("SB1",AD6:AD33,1,FALSE) -> SB1 | AE38: =VLOOKUP("SB1",AE6:AE33,1,FALSE) -> #N/A | AF38: =VLOOKUP("SB1",AF5:AF33,1,FALSE) -> #N/A | AG38: =VLOOKUP("SB1",AG6:AG33,1,FALSE) -> SB1
